Workbook

Sheet Detailed results
E1: SSPR-Run #1 | G1: SSPR-Run #2 | I1: SSPR-Run #3 | K1: SSPR-Run #4 | M1: SSPR-Run #5 | O1: SSPR-Run #6 | Q1: SSPR-Run #7 | S1: SSPR-Run #8 | U1: SSPR-Run #9 | W1: SSPR-Run #10 | Y1: SS-TS | Z1: Matta's GA results | AD1: TS results | AH1: hPSOTS results | AL1: SSPR results | AP1: hPSOTS runs
A2: Problem | B2: No. of Jobs | C2: No. of Stages | D2: LB | E2: Cmax | F2: Time (ms) | G2: Cmax | H2: Time (ms) | I2: Cmax | J2: Time (ms) | K2: Cmax | L2: Time (ms) | M2: Cmax | N2: Time (ms) | O2: Cmax | P2: Time (ms) | Q2: Cmax | R2: Time (ms) | S2: Cmax | T2: Time (ms) | U2: Cmax | V2: Time (ms) | W2: Cmax | X2: Time (ms) | Y2: Cmax | Z2: Avg. Cmax | AA2: Best Cmax | AB2: Mean dev. | AC2: Avg. Time | AD2: Avg. Cmax | AE2: Best Cmax | AF2: Mean dev. | AG2: Avg. Time | AH2: Avg. Cmax | AI2: Best Cmax | AJ2: Mean dev. | AK2: Avg. Time | AL2: Avg. Cmax | AM2: Best Cmax | AN2: Mean dev. | AO2: Avg. Time | AP2: Cmax1 | AQ2: Time1 | AR2: Cmax2 | AS2: Time2 | AT2: Cmax3 | AU2: Time3 | AV2: Cmax4 | AW2: Time4 | AX2: Cmax5 | AY2: Time5 | AZ2: Cmax6 | BA2: Time6 | BB2: Cmax7 | BC2: Time7 | BD2: Cmax8 | BE2: Time8 | BF2: Cmax9 | BG2: Time9 | BH2: Cmax10 | BI2: Time10
A3: S2-P1 | B3: 22 | C3: 2 | D3: 30 | Y3: 30 | Z3: 30 | AA3: 30 | AB3: 0 | AC3: 3.19 | AD3: 30 | AE3: 30 | AF3: 0 | AG3: 0.02 | AH3: =AVERAGE(AP3,AR3,AT3,AV3,AX3,AZ3,BB3,BD3,BF3,BH3) -> 30 | AI3: =MIN(AP3,AR3,AT3,AV3,AX3,AZ3,BB3,BD3,BF3,BH3) -> 30 | AJ3: =(AH3-D3)/D3 -> 0 | AK3: =AVERAGE(AQ3,AS3,AU3,AW3,AY3,BA3,BC3,BE3,BG3,BI3)/1000 -> 0.0077 | AP3: 30 | AQ3: 8 | AR3: 30 | AS3: 12 | AT3: 30 | AU3: 9 | AV3: 30 | AW3: 8 | AX3: 30 | AY3: 5 | AZ3: 30 | BA3: 6 | BB3: 30 | BC3: 7 | BD3: 30 | BE3: 9 | BF3: 30 | BG3: 8 | BH3: 30 | BI3: 5
A4: S2-P2 | B4: 32 | C4: 2 | D4: 10 | Y4: 11 | Z4: 11 | AA4: 11 | AB4: 10 | AC4: 2.3 | AD4: 11 | AE4: 11 | AF4: 10 | AG4: 0.05 | AH4: =AVERAGE(AP4,AR4,AT4,AV4,AX4,AZ4,BB4,BD4,BF4,BH4) -> 11 | AI4: =MIN(AP4,AR4,AT4,AV4,AX4,AZ4,BB4,BD4,BF4,BH4) -> 11 | AJ4: =(AH4-D4)/D4 -> 0.1 | AK4: =AVERAGE(AQ4,AS4,AU4,AW4,AY4,BA4,BC4,BE4,BG4,BI4)/1000 -> 0.4699 | AP4: 11 | AQ4: 523 | AR4: 11 | AS4: 390 | AT4: 11 | AU4: 388 | AV4: 11 | AW4: 638 | AX4: 11 | AY4: 456 | AZ4: 11 | BA4: 365 | BB4: 11 | BC4: 473 | BD4: 11 | BE4: 632 | BF4: 11 | BG4: 420 | BH4: 11 | BI4: 414
A5: S2-P3 | B5: 24 | C5: 2 | D5: 18 | Y5: 18 | Z5: 18 | AA5: 18 | AB5: 0 | AC5: 2.27 | AD5: 18 | AE5: 18 | AF5: 0 | AG5: 0 | AH5: =AVERAGE(AP5,AR5,AT5,AV5,AX5,AZ5,BB5,BD5,BF5,BH5) -> 18 | AI5: =MIN(AP5,AR5,AT5,AV5,AX5,AZ5,BB5,BD5,BF5,BH5) -> 18 | AJ5: =(AH5-D5)/D5 -> 0 | AK5: =AVERAGE(AQ5,AS5,AU5,AW5,AY5,BA5,BC5,BE5,BG5,BI5)/1000 -> 0.0107 | AP5: 18 | AQ5: 6 | AR5: 18 | AS5: 9 | AT5: 18 | AU5: 50 | AV5: 18 | AW5: 7 | AX5: 18 | AY5: 6 | AZ5: 18 | BA5: 6 | BB5: 18 | BC5: 5 | BD5: 18 | BE5: 8 | BF5: 18 | BG5: 5 | BH5: 18 | BI5: 5
A6: S2-P4 | B6: 20 | C6: 2 | D6: 16 | Y6: 18 | Z6: 18 | AA6: 18 | AB6: 12.5 | AC6: 1.58 | AD6: 18 | AE6: 18 | AF6: 12.5 | AG6: 0.02 | AH6: =AVERAGE(AP6,AR6,AT6,AV6,AX6,AZ6,BB6,BD6,BF6,BH6) -> 18 | AI6: =MIN(AP6,AR6,AT6,AV6,AX6,AZ6,BB6,BD6,BF6,BH6) -> 18 | AJ6: =(AH6-D6)/D6 -> 0.125 | AK6: =AVERAGE(AQ6,AS6,AU6,AW6,AY6,BA6,BC6,BE6,BG6,BI6)/1000 -> 0.3767 | AP6: 18 | AQ6: 325 | AR6: 18 | AS6: 451 | AT6: 18 | AU6: 406 | AV6: 18 | AW6: 345 | AX6: 18 | AY6: 404 | AZ6: 18 | BA6: 335 | BB6: 18 | BC6: 329 | BD6: 18 | BE6: 436 | BF6: 18 | BG6: 372 | BH6: 18 | BI6: 364
A7: S2-P5 | B7: 29 | C7: 2 | D7: 27 | Y7: 31 | Z7: 31 | AA7: 31 | AB7: 14.8 | AC7: 4.77 | AD7: 31 | AE7: 31 | AF7: 14.8 | AG7: 0.04 | AH7: =AVERAGE(AP7,AR7,AT7,AV7,AX7,AZ7,BB7,BD7,BF7,BH7) -> 31 | AI7: =MIN(AP7,AR7,AT7,AV7,AX7,AZ7,BB7,BD7,BF7,BH7) -> 31 | AJ7: =(AH7-D7)/D7 -> 0.14814815 | AK7: =AVERAGE(AQ7,AS7,AU7,AW7,AY7,BA7,BC7,BE7,BG7,BI7)/1000 -> 0.4359 | AP7: 31 | AQ7: 422 | AR7: 31 | AS7: 552 | AT7: 31 | AU7: 399 | AV7: 31 | AW7: 425 | AX7: 31 | AY7: 506 | AZ7: 31 | BA7: 474 | BB7: 31 | BC7: 420 | BD7: 31 | BE7: 402 | BF7: 31 | BG7: 400 | BH7: 31 | BI7: 359
A8: S2-P6 | B8: 30 | C8: 2 | D8: 12 | Y8: 12 | Z8: 12 | AA8: 12 | AB8: 0 | AC8: 2.37 | AD8: 12 | AE8: 12 | AF8: 0 | AG8: 0 | AH8: =AVERAGE(AP8,AR8,AT8,AV8,AX8,AZ8,BB8,BD8,BF8,BH8) -> 12 | AI8: =MIN(AP8,AR8,AT8,AV8,AX8,AZ8,BB8,BD8,BF8,BH8) -> 12 | AJ8: =(AH8-D8)/D8 -> 0 | AK8: =AVERAGE(AQ8,AS8,AU8,AW8,AY8,BA8,BC8,BE8,BG8,BI8)/1000 -> 0.0055 | AP8: 12 | AQ8: 8 | AR8: 12 | AS8: 7 | AT8: 12 | AU8: 7 | AV8: 12 | AW8: 5 | AX8: 12 | AY8: 5 | AZ8: 12 | BA8: 4 | BB8: 12 | BC8: 5 | BD8: 12 | BE8: 5 | BF8: 12 | BG8: 4 | BH8: 12 | BI8: 5
A9: S2-P7 | B9: 28 | C9: 2 | D9: 27 | Y9: 30 | Z9: 30 | AA9: 30 | AB9: 11.1 | AC9: 4.19 | AD9: 30 | AE9: 30 | AF9: 11.1 | AG9: 0.02 | AH9: =AVERAGE(AP9,AR9,AT9,AV9,AX9,AZ9,BB9,BD9,BF9,BH9) -> 30 | AI9: =MIN(AP9,AR9,AT9,AV9,AX9,AZ9,BB9,BD9,BF9,BH9) -> 30 | AJ9: =(AH9-D9)/D9 -> 0.11111111 | AK9: =AVERAGE(AQ9,AS9,AU9,AW9,AY9,BA9,BC9,BE9,BG9,BI9)/1000 -> 0.4372 | AP9: 30 | AQ9: 398 | AR9: 30 | AS9: 390 | AT9: 30 | AU9: 453 | AV9: 30 | AW9: 451 | AX9: 30 | AY9: 408 | AZ9: 30 | BA9: 391 | BB9: 30 | BC9: 393 | BD9: 30 | BE9: 411 | BF9: 30 | BG9: 454 | BH9: 30 | BI9: 623
A10: S2-P8 | B10: 10 | C10: 2 | D10: 16 | Y10: 16 | Z10: 16 | AA10: 16 | AB10: 0 | AC10: 0.53 | AD10: 16 | AE10: 16 | AF10: 0 | AG10: 0 | AH10: =AVERAGE(AP10,AR10,AT10,AV10,AX10,AZ10,BB10,BD10,BF10,BH10) -> 16 | AI10: =MIN(AP10,AR10,AT10,AV10,AX10,AZ10,BB10,BD10,BF10,BH10) -> 16 | AJ10: =(AH10-D10)/D10 -> 0 | AK10: =AVERAGE(AQ10,AS10,AU10,AW10,AY10,BA10,BC10,BE10,BG10,BI10)/1000 -> 0.0024 | AP10: 16 | AQ10: 3 | AR10: 16 | AS10: 2 | AT10: 16 | AU10: 2 | AV10: 16 | AW10: 3 | AX10: 16 | AY10: 2 | AZ10: 16 | BA10: 2 | BB10: 16 | BC10: 3 | BD10: 16 | BE10: 3 | BF10: 16 | BG10: 2 | BH10: 16 | BI10: 2
A11: S2-P9 | B11: 30 | C11: 2 | D11: 22 | Y11: 22 | Z11: 22 | AA11: 22 | AB11: 0 | AC11: 4.37 | AD11: 22 | AE11: 22 | AF11: 0 | AG11: 0 | AH11: =AVERAGE(AP11,AR11,AT11,AV11,AX11,AZ11,BB11,BD11,BF11,BH11) -> 22 | AI11: =MIN(AP11,AR11,AT11,AV11,AX11,AZ11,BB11,BD11,BF11,BH11) -> 22 | AJ11: =(AH11-D11)/D11 -> 0 | AK11: =AVERAGE(AQ11,AS11,AU11,AW11,AY11,BA11,BC11,BE11,BG11,BI11)/1000 -> 0.0052 | AP11: 22 | AQ11: 6 | AR11: 22 | AS11: 6 | AT11: 22 | AU11: 5 | AV11: 22 | AW11: 5 | AX11: 22 | AY11: 5 | AZ11: 22 | BA11: 7 | BB11: 22 | BC11: 4 | BD11: 22 | BE11: 5 | BF11: 22 | BG11: 4 | BH11: 22 | BI11: 5
A12: S2-P10 | B12: 16 | C12: 2 | D12: 28 | Y12: 28 | Z12: 28 | AA12: 28 | AB12: 0 | AC12: 1.61 | AD12: 28 | AE12: 28 | AF12: 0 | AG12: 0.02 | AH12: =AVERAGE(AP12,AR12,AT12,AV12,AX12,AZ12,BB12,BD12,BF12,BH12) -> 28 | AI12: =MIN(AP12,AR12,AT12,AV12,AX12,AZ12,BB12,BD12,BF12,BH12) -> 28 | AJ12: =(AH12-D12)/D12 -> 0 | AK12: =AVERAGE(AQ12,AS12,AU12,AW12,AY12,BA12,BC12,BE12,BG12,BI12)/1000 -> 0.005 | AP12: 28 | AQ12: 6 | AR12: 28 | AS12: 9 | AT12: 28 | AU12: 5 | AV12: 28 | AW12: 3 | AX12: 28 | AY12: 5 | AZ12: 28 | BA12: 7 | BB12: 28 | BC12: 3 | BD12: 28 | BE12: 5 | BF12: 28 | BG12: 4 | BH12: 28 | BI12: 3
A13: S2-P11 | B13: 40 | C13: 2 | D13: 14 | Y13: 14 | Z13: 14 | AA13: 14 | AB13: 0 | AC13: 4.8 | AD13: 14 | AE13: 14 | AF13: 0 | AG13: 0 | AH13: =AVERAGE(AP13,AR13,AT13,AV13,AX13,AZ13,BB13,BD13,BF13,BH13) -> 14 | AI13: =MIN(AP13,AR13,AT13,AV13,AX13,AZ13,BB13,BD13,BF13,BH13) -> 14 | AJ13: =(AH13-D13)/D13 -> 0 | AK13: =AVERAGE(AQ13,AS13,AU13,AW13,AY13,BA13,BC13,BE13,BG13,BI13)/1000 -> 0.0082 | AP13: 14 | AQ13: 12 | AR13: 14 | AS13: 11 | AT13: 14 | AU13: 11 | AV13: 14 | AW13: 9 | AX13: 14 | AY13: 6 | AZ13: 14 | BA13: 6 | BB13: 14 | BC13: 7 | BD13: 14 | BE13: 7 | BF13: 14 | BG13: 6 | BH13: 14 | BI13: 7
A14: S2-P12 | B14: 34 | C14: 2 | D14: 36 | Y14: 39 | Z14: 39 | AA14: 39 | AB14: 8.3 | AC14: 7.44 | AD14: 39 | AE14: 39 | AF14: 8.3 | AG14: 0.04 | AH14: =AVERAGE(AP14,AR14,AT14,AV14,AX14,AZ14,BB14,BD14,BF14,BH14) -> 39 | AI14: =MIN(AP14,AR14,AT14,AV14,AX14,AZ14,BB14,BD14,BF14,BH14) -> 39 | AJ14: =(AH14-D14)/D14 -> 0.083333333 | AK14: =AVERAGE(AQ14,AS14,AU14,AW14,AY14,BA14,BC14,BE14,BG14,BI14)/1000 -> 0.4829 | AP14: 39 | AQ14: 450 | AR14: 39 | AS14: 497 | AT14: 39 | AU14: 449 | AV14: 39 | AW14: 508 | AX14: 39 | AY14: 500 | AZ14: 39 | BA14: 446 | BB14: 39 | BC14: 413 | BD14: 39 | BE14: 529 | BF14: 39 | BG14: 538 | BH14: 39 | BI14: 499
... A27: S2-P25 | B27: 21 | C27: 2 | D27: 10 | Y27: 10 | Z27: 10 | AA27: 10 | AB27: 0 | AC27: 1.11 | AD27: 10 | AE27: 10 | AF27: 0 | AG27: 0.02 | AH27: =AVERAGE(AP27,AR27,AT27,AV27,AX27,AZ27,BB27,BD27,BF27,BH27) -> 10 | AI27: =MIN(AP27,AR27,AT27,AV27,AX27,AZ27,BB27,BD27,BF27,BH27) -> 10 | AJ27: =(AH27-D27)/D27 -> 0 | AK27: =AVERAGE(AQ27,AS27,AU27,AW27,AY27,BA27,BC27,BE27,BG27,BI27)/1000 -> 0.0078 | AP27: 10 | AQ27: 10 | AR27: 10 | AS27: 6 | AT27: 10 | AU27: 7 | AV27: 10 | AW27: 8 | AX27: 10 | AY27: 6 | AZ27: 10 | BA27: 14 | BB27: 10 | BC27: 10 | BD27: 10 | BE27: 4 | BF27: 10 | BG27: 8 | BH27: 10 | BI27: 5
A28: S4-P1 | B28: 49 | C28: 4 | D28: 26 | E28: 30 | F28: 20823 | G28: 29 | H28: 21033 | I28: 30 | J28: 20389 | K28: 30 | L28: 19452 | M28: 29 | N28: 20633 | O28: 29 | P28: 20661 | Q28: 29 | R28: 20103 | S28: 29 | T28: 20858 | U28: 30 | V28: 20177 | W28: 29 | X28: 20473 | Y28: 29 | Z28: 31.9 | AA28: 31 | AB28: 22.7 | AC28: 14.19 | AD28: 33 | AE28: 33 | AF28: 26.9 | AG28: 19.59 | AH28: =AVERAGE(AP28,AR28,AT28,AV28,AX28,AZ28,BB28,BD28,BF28,BH28) -> 30.9 | AI28: =MIN(AP28,AR28,AT28,AV28,AX28,AZ28,BB28,BD28,BF28,BH28) -> 30 | AJ28: =(AH28-D28)/D28 -> 0.18846154 | AK28: =AVERAGE(AQ28,AS28,AU28,AW28,AY28,BA28,BC28,BE28,BG28,BI28)/1000 -> 18.9078 | AL28: =AVERAGE(E28,G28,I28,K28,M28,O28,Q28,S28,U28,W28) -> 29.4 | AM28: =MIN(E28,G28,I28,K28,M28,O28,Q28,S28,U28,W28) -> 29 | AN28: =(AL28-D28)/D28 -> 0.13076923 | AO28: =AVERAGE(F28,H28,J28,L28,N28,P28,R28,T28,V28,X28)/1000 -> 20.4602 | AP28: 31 | AQ28: 17717 | AR28: 31 | AS28: 19600 | AT28: 31 | AU28: 19600 | AV28: 31 | AW28: 19600 | AX28: 31 | AY28: 19600 | AZ28: 31 | BA28: 17066 | BB28: 31 | BC28: 17095 | BD28: 31 | BE28: 19600 | BF28: 30 | BG28: 19600 | BH28: 31 | BI28: 19600 | BM28: 47549 | BN28: 44288 | BO28: 44554 | BP28: 52947 | BQ28: 41886 | BS28: =AVERAGE(BM28:BQ28) -> 46244.8 | BT28: =BS28/AO28/1000 -> 2.2602321
A29: S4-P2 | B29: 39 | C29: 4 | D29: 21 | E29: 21 | F29: 7 | G29: 21 | H29: 7 | I29: 21 | J29: 7 | K29: 21 | L29: 7 | M29: 21 | N29: 7 | O29: 21 | P29: 7 | Q29: 21 | R29: 8 | S29: 21 | T29: 8 | U29: 21 | V29: 7 | W29: 21 | X29: 8 | Y29: 21 | Z29: 21 | AA29: 21 | AB29: 0 | AC29: 5.85 | AD29: 21 | AE29: 21 | AF29: 0 | AG29: 0 | AH29: =AVERAGE(AP29,AR29,AT29,AV29,AX29,AZ29,BB29,BD29,BF29,BH29) -> 21 | AI29: =MIN(AP29,AR29,AT29,AV29,AX29,AZ29,BB29,BD29,BF29,BH29) -> 21 | AJ29: =(AH29-D29)/D29 -> 0 | AK29: =AVERAGE(AQ29,AS29,AU29,AW29,AY29,BA29,BC29,BE29,BG29,BI29)/1000 -> 0.0113 | AL29: =AVERAGE(E29,G29,I29,K29,M29,O29,Q29,S29,U29,W29) -> 21 | AM29: =MIN(E29,G29,I29,K29,M29,O29,Q29,S29,U29,W29) -> 21 | AN29: =(AL29-D29)/D29 -> 0 | AO29: =AVERAGE(F29,H29,J29,L29,N29,P29,R29,T29,V29,X29)/1000 -> 0.0073 | AP29: 21 | AQ29: 10 | AR29: 21 | AS29: 14 | AT29: 21 | AU29: 10 | AV29: 21 | AW29: 14 | AX29: 21 | AY29: 10 | AZ29: 21 | BA29: 10 | BB29: 21 | BC29: 10 | BD29: 21 | BE29: 10 | BF29: 21 | BG29: 11 | BH29: 21 | BI29: 14
A30: S4-P3 | B30: 63 | C30: 4 | D30: 48 | E30: 51 | F30: 26493 | G30: 51 | H30: 26395 | I30: 51 | J30: 26268 | K30: 51 | L30: 26345 | M30: 51 | N30: 26284 | O30: 51 | P30: 26153 | Q30: 51 | R30: 26225 | S30: 51 | T30: 26036 | U30: 51 | V30: 25840 | W30: 51 | X30: 25695 | Y30: 51 | Z30: 56.1 | AA30: 54 | AB30: 16.9 | AC30: 35.46 | AD30: 54 | AE30: 51 | AF30: 12.5 | AG30: 3.79 | AH30: =AVERAGE(AP30,AR30,AT30,AV30,AX30,AZ30,BB30,BD30,BF30,BH30) -> 52.2 | AI30: =MIN(AP30,AR30,AT30,AV30,AX30,AZ30,BB30,BD30,BF30,BH30) -> 51 | AJ30: =(AH30-D30)/D30 -> 0.0875 | AK30: =AVERAGE(AQ30,AS30,AU30,AW30,AY30,BA30,BC30,BE30,BG30,BI30)/1000 -> 20.4504 | AL30: =AVERAGE(E30,G30,I30,K30,M30,O30,Q30,S30,U30,W30) -> 51 | AM30: =MIN(E30,G30,I30,K30,M30,O30,Q30,S30,U30,W30) -> 51 | AN30: =(AL30-D30)/D30 -> 0.0625 | AO30: =AVERAGE(F30,H30,J30,L30,N30,P30,R30,T30,V30,X30)/1000 -> 26.1734 | AP30: 51 | AQ30: 19501 | AR30: 51 | AS30: 23427 | AT30: 54 | AU30: 20308 | AV30: 54 | AW30: 18841 | AX30: 51 | AY30: 19784 | AZ30: 51 | BA30: 20951 | BB30: 51 | BC30: 18635 | BD30: 54 | BE30: 18428 | BF30: 54 | BG30: 24188 | BH30: 51 | BI30: 20441
A31: S4-P4 | B31: 38 | C31: 4 | D31: 27 | E31: 27 | F31: 3739 | G31: 27 | H31: 1616 | I31: 27 | J31: 6203 | K31: 27 | L31: 3088 | M31: 27 | N31: 2927 | O31: 27 | P31: 1407 | Q31: 27 | R31: 2553 | S31: 27 | T31: 3370 | U31: 27 | V31: 2387 | W31: 27 | X31: 3123 | Y31: 27 | Z31: 28.8 | AA31: 27 | AB31: 6.7 | AC31: 7.87 | AD31: 30 | AE31: 30 | AF31: 11.1 | AG31: 7.15 | AH31: =AVERAGE(AP31,AR31,AT31,AV31,AX31,AZ31,BB31,BD31,BF31,BH31) -> 29.4 | AI31: =MIN(AP31,AR31,AT31,AV31,AX31,AZ31,BB31,BD31,BF31,BH31) -> 27 | AJ31: =(AH31-D31)/D31 -> 0.088888889 | AK31: =AVERAGE(AQ31,AS31,AU31,AW31,AY31,BA31,BC31,BE31,BG31,BI31)/1000 -> 12.3872 | AL31: =AVERAGE(E31,G31,I31,K31,M31,O31,Q31,S31,U31,W31) -> 27 | AM31: =MIN(E31,G31,I31,K31,M31,O31,Q31,S31,U31,W31) -> 27 | AN31: =(AL31-D31)/D31 -> 0 | AO31: =AVERAGE(F31,H31,J31,L31,N31,P31,R31,T31,V31,X31)/1000 -> 3.0413 | AP31: 30 | AQ31: 15203 | AR31: 27 | AS31: 1237 | AT31: 30 | AU31: 14709 | AV31: 30 | AW31: 14934 | AX31: 30 | AY31: 15200 | AZ31: 30 | BA31: 15200 | BB31: 30 | BC31: 15200 | BD31: 30 | BE31: 15200 | BF31: 30 | BG31: 15200 | BH31: 27 | BI31: 1789
A32: S4-P5 | B32: 56 | C32: 4 | D32: 32 | E32: 32 | F32: 476 | G32: 32 | H32: 19 | I32: 32 | J32: 240 | K32: 32 | L32: 916 | M32: 32 | N32: 20 | O32: 32 | P32: 77 | Q32: 32 | R32: 396 | S32: 32 | T32: 486 | U32: 32 | V32: 18 | W32: 32 | X32: 244 | Y32: 32 | Z32: 33.6 | AA32: 32 | AB32: 5 | AC32: 16.61 | AD32: 32 | AE32: 32 | AF32: 0 | AG32: 0 | AH32: =AVERAGE(AP32,AR32,AT32,AV32,AX32,AZ32,BB32,BD32,BF32,BH32) -> 32 | AI32: =MIN(AP32,AR32,AT32,AV32,AX32,AZ32,BB32,BD32,BF32,BH32) -> 32 | AJ32: =(AH32-D32)/D32 -> 0 | AK32: =AVERAGE(AQ32,AS32,AU32,AW32,AY32,BA32,BC32,BE32,BG32,BI32)/1000 -> 0.0233 | AL32: =AVERAGE(E32,G32,I32,K32,M32,O32,Q32,S32,U32,W32) -> 32 | AM32: =MIN(E32,G32,I32,K32,M32,O32,Q32,S32,U32,W32) -> 32 | AN32: =(AL32-D32)/D32 -> 0 | AO32: =AVERAGE(F32,H32,J32,L32,N32,P32,R32,T32,V32,X32)/1000 -> 0.2892 | AP32: 32 | AQ32: 26 | AR32: 32 | AS32: 22 | AT32: 32 | AU32: 23 | AV32: 32 | AW32: 22 | AX32: 32 | AY32: 23 | AZ32: 32 | BA32: 22 | BB32: 32 | BC32: 23 | BD32: 32 | BE32: 22 | BF32: 32 | BG32: 23 | BH32: 32 | BI32: 27
A33: S4-P6 | B33: 60 | C33: 4 | D33: 25 | E33: 28 | F33: 20763 | G33: 28 | H33: 20425 | I33: 28 | J33: 20361 | K33: 28 | L33: 20176 | M33: 28 | N33: 20758 | O33: 28 | P33: 20707 | Q33: 28 | R33: 20563 | S33: 28 | T33: 20511 | U33: 28 | V33: 20689 | W33: 28 | X33: 20716 | Y33: 28 | Z33: 27.9 | AA33: 26 | AB33: 11.6 | AC33: 16.62 | AD33: 28.1 | AE33: 28 | AF33: 12.4 | AG33: 12.39 | AH33: =AVERAGE(AP33,AR33,AT33,AV33,AX33,AZ33,BB33,BD33,BF33,BH33) -> 26 | AI33: =MIN(AP33,AR33,AT33,AV33,AX33,AZ33,BB33,BD33,BF33,BH33) -> 26 | AJ33: =(AH33-D33)/D33 -> 0.04 | AK33: =AVERAGE(AQ33,AS33,AU33,AW33,AY33,BA33,BC33,BE33,BG33,BI33)/1000 -> 21.5627 | AL33: =AVERAGE(E33,G33,I33,K33,M33,O33,Q33,S33,U33,W33) -> 28 | AM33: =MIN(E33,G33,I33,K33,M33,O33,Q33,S33,U33,W33) -> 28 | AN33: =(AL33-D33)/D33 -> 0.12 | AO33: =AVERAGE(F33,H33,J33,L33,N33,P33,R33,T33,V33,X33)/1000 -> 20.5669 | AP33: 26 | AQ33: 20193 | AR33: 26 | AS33: 23974 | AT33: 26 | AU33: 21797 | AV33: 26 | AW33: 24000 | AX33: 26 | AY33: 21697 | AZ33: 26 | BA33: 20004 | BB33: 26 | BC33: 15861 | BD33: 26 | BE33: 23358 | BF33: 26 | BG33: 24000 | BH33: 26 | BI33: 20743
A34: S4-P7 | B34: 53 | C34: 4 | D34: 36 | E34: 36 | F34: 9 | G34: 36 | H34: 8 | I34: 36 | J34: 7 | K34: 36 | L34: 9 | M34: 36 | N34: 7 | O34: 36 | P34: 10 | Q34: 36 | R34: 8 | S34: 36 | T34: 9 | U34: 36 | V34: 10 | W34: 36 | X34: 6 | Y34: 36 | Z34: 36 | AA34: 36 | AB34: 0 | AC34: 16.93 | AD34: 40 | AE34: 40 | AF34: 11.1 | AG34: 10.33 | AH34: =AVERAGE(AP34,AR34,AT34,AV34,AX34,AZ34,BB34,BD34,BF34,BH34) -> 36 | AI34: =MIN(AP34,AR34,AT34,AV34,AX34,AZ34,BB34,BD34,BF34,BH34) -> 36 | AJ34: =(AH34-D34)/D34 -> 0 | AK34: =AVERAGE(AQ34,AS34,AU34,AW34,AY34,BA34,BC34,BE34,BG34,BI34)/1000 -> 0.1081 | AL34: =AVERAGE(E34,G34,I34,K34,M34,O34,Q34,S34,U34,W34) -> 36 | AM34: =MIN(E34,G34,I34,K34,M34,O34,Q34,S34,U34,W34) -> 36 | AN34: =(AL34-D34)/D34 -> 0 | AO34: =AVERAGE(F34,H34,J34,L34,N34,P34,R34,T34,V34,X34)/1000 -> 0.0083 | AP34: 36 | AQ34: 138 | AR34: 36 | AS34: 94 | AT34: 36 | AU34: 175 | AV34: 36 | AW34: 82 | AX34: 36 | AY34: 71 | AZ34: 36 | BA34: 74 | BB34: 36 | BC34: 180 | BD34: 36 | BE34: 65 | BF34: 36 | BG34: 39 | BH34: 36 | BI34: 163
A35: S4-P8 | B35: 40 | C35: 4 | D35: 33 | E35: 33 | F35: 13 | G35: 33 | H35: 13 | I35: 33 | J35: 13 | K35: 33 | L35: 13 | M35: 33 | N35: 13 | O35: 33 | P35: 12 | Q35: 33 | R35: 13 | S35: 33 | T35: 12 | U35: 33 | V35: 13 | W35: 33 | X35: 36 | Y35: 33 | Z35: 33 | AA35: 33 | AB35: 0 | AC35: 9.32 | AD35: 34 | AE35: 34 | AF35: 3 | AG35: 14.46 | AH35: =AVERAGE(AP35,AR35,AT35,AV35,AX35,AZ35,BB35,BD35,BF35,BH35) -> 33 | AI35: =MIN(AP35,AR35,AT35,AV35,AX35,AZ35,BB35,BD35,BF35,BH35) -> 33 | AJ35: =(AH35-D35)/D35 -> 0 | AK35: =AVERAGE(AQ35,AS35,AU35,AW35,AY35,BA35,BC35,BE35,BG35,BI35)/1000 -> 0.0194 | AL35: =AVERAGE(E35,G35,I35,K35,M35,O35,Q35,S35,U35,W35) -> 33 | AM35: =MIN(E35,G35,I35,K35,M35,O35,Q35,S35,U35,W35) -> 33 | AN35: =(AL35-D35)/D35 -> 0 | AO35: =AVERAGE(F35,H35,J35,L35,N35,P35,R35,T35,V35,X35)/1000 -> 0.0151 | AP35: 33 | AQ35: 32 | AR35: 33 | AS35: 14 | AT35: 33 | AU35: 13 | AV35: 33 | AW35: 23 | AX35: 33 | AY35: 15 | AZ35: 33 | BA35: 17 | BB35: 33 | BC35: 15 | BD35: 33 | BE35: 13 | BF35: 33 | BG35: 36 | BH35: 33 | BI35: 16
A36: S4-P9 | B36: 65 | C36: 4 | D36: 39 | E36: 42 | F36: 23515 | G36: 42 | H36: 23977 | I36: 42 | J36: 22841 | K36: 42 | L36: 21428 | M36: 41 | N36: 22621 | O36: 42 | P36: 22109 | Q36: 42 | R36: 22744 | S36: 42 | T36: 22515 | U36: 42 | V36: 22215 | W36: 42 | X36: 22772 | Y36: 42 | Z36: 47.8 | AA36: 46 | AB36: 22.6 | AC36: 33.49 | AD36: 48 | AE36: 47 | AF36: 23.1 | AG36: 26 | AH36: =AVERAGE(AP36,AR36,AT36,AV36,AX36,AZ36,BB36,BD36,BF36,BH36) -> 44.2 | AI36: =MIN(AP36,AR36,AT36,AV36,AX36,AZ36,BB36,BD36,BF36,BH36) -> 41 | AJ36: =(AH36-D36)/D36 -> 0.13333333 | AK36: =AVERAGE(AQ36,AS36,AU36,AW36,AY36,BA36,BC36,BE36,BG36,BI36)/1000 -> 21.2754 | AL36: =AVERAGE(E36,G36,I36,K36,M36,O36,Q36,S36,U36,W36) -> 41.9 | AM36: =MIN(E36,G36,I36,K36,M36,O36,Q36,S36,U36,W36) -> 41 | AN36: =(AL36-D36)/D36 -> 0.074358974 | AO36: =AVERAGE(F36,H36,J36,L36,N36,P36,R36,T36,V36,X36)/1000 -> 22.6737 | AP36: 41 | AQ36: 25294 | AR36: 46 | AS36: 24204 | AT36: 46 | AU36: 18576 | AV36: 46 | AW36: 21585 | AX36: 43 | AY36: 21234 | AZ36: 43 | BA36: 25074 | BB36: 43 | BC36: 20353 | BD36: 46 | BE36: 16909 | BF36: 42 | BG36: 23665 | BH36: 46 | BI36: 15860
A37: S4-P10 | B37: 53 | C37: 4 | D37: 56 | E37: 56 | F37: 8 | G37: 56 | H37: 8 | I37: 56 | J37: 19 | K37: 56 | L37: 19 | M37: 56 | N37: 9 | O37: 56 | P37: 18 | Q37: 56 | R37: 17 | S37: 56 | T37: 9 | U37: 56 | V37: 19 | W37: 56 | X37: 9 | Y37: 56 | Z37: 57.6 | AA37: 56 | AB37: 2.9 | AC37: 24.6 | AD37: 56 | AE37: 56 | AF37: 0 | AG37: 0 | AH37: =AVERAGE(AP37,AR37,AT37,AV37,AX37,AZ37,BB37,BD37,BF37,BH37) -> 56 | AI37: =MIN(AP37,AR37,AT37,AV37,AX37,AZ37,BB37,BD37,BF37,BH37) -> 56 | AJ37: =(AH37-D37)/D37 -> 0 | AK37: =AVERAGE(AQ37,AS37,AU37,AW37,AY37,BA37,BC37,BE37,BG37,BI37)/1000 -> 0.1858 | AL37: =AVERAGE(E37,G37,I37,K37,M37,O37,Q37,S37,U37,W37) -> 56 | AM37: =MIN(E37,G37,I37,K37,M37,O37,Q37,S37,U37,W37) -> 56 | AN37: =(AL37-D37)/D37 -> 0 | AO37: =AVERAGE(F37,H37,J37,L37,N37,P37,R37,T37,V37,X37)/1000 -> 0.0135 | AP37: 56 | AQ37: 23 | AR37: 56 | AS37: 20 | AT37: 56 | AU37: 20 | AV37: 56 | AW37: 921 | AX37: 56 | AY37: 19 | AZ37: 56 | BA37: 21 | BB37: 56 | BC37: 20 | BD37: 56 | BE37: 773 | BF37: 56 | BG37: 21 | BH37: 56 | BI37: 20
A38: S4-P11 | B38: 55 | C38: 4 | D38: 40 | E38: 40 | F38: 18 | G38: 40 | H38: 18 | I38: 40 | J38: 19 | K38: 40 | L38: 19 | M38: 40 | N38: 8 | O38: 40 | P38: 16 | Q38: 40 | R38: 18 | S38: 40 | T38: 19 | U38: 40 | V38: 20 | W38: 40 | X38: 17 | Y38: 40 | Z38: 43.7 | AA38: 43 | AB38: 9.3 | AC38: 22.2 | AD38: 40.6 | AE38: 40 | AF38: 1.5 | AG38: 0 | AH38: =AVERAGE(AP38,AR38,AT38,AV38,AX38,AZ38,BB38,BD38,BF38,BH38) -> 40.8 | AI38: =MIN(AP38,AR38,AT38,AV38,AX38,AZ38,BB38,BD38,BF38,BH38) -> 40 | AJ38: =(AH38-D38)/D38 -> 0.02 | AK38: =AVERAGE(AQ38,AS38,AU38,AW38,AY38,BA38,BC38,BE38,BG38,BI38)/1000 -> 16.6627 | AL38: =AVERAGE(E38,G38,I38,K38,M38,O38,Q38,S38,U38,W38) -> 40 | AM38: =MIN(E38,G38,I38,K38,M38,O38,Q38,S38,U38,W38) -> 40 | AN38: =(AL38-D38)/D38 -> 0 | AO38: =AVERAGE(F38,H38,J38,L38,N38,P38,R38,T38,V38,X38)/1000 -> 0.0172 | AP38: 41 | AQ38: 22000 | AR38: 41 | AS38: 22000 | AT38: 40 | AU38: 3586 | AV38: 41 | AW38: 16661 | AX38: 41 | AY38: 22000 | AZ38: 41 | BA38: 22000 | BB38: 41 | BC38: 19553 | BD38: 41 | BE38: 16804 | BF38: 41 | BG38: 22000 | BH38: 40 | BI38: 23
A39: S4-P12 | B39: 58 | C39: 4 | D39: 30 | E39: 32 | F39: 22150 | G39: 32 | H39: 21940 | I39: 32 | J39: 22270 | K39: 32 | L39: 23097 | M39: 32 | N39: 22959 | O39: 32 | P39: 21553 | Q39: 32 | R39: 21949 | S39: 32 | T39: 22062 | U39: 32 | V39: 22160 | W39: 32 | X39: 22074 | Y39: 32 | Z39: 33 | AA39: 32 | AB39: 10 | AC39: 19.24 | AD39: 37.2 | AE39: 36 | AF39: 24 | AG39: 1.1 | AH39: =AVERAGE(AP39,AR39,AT39,AV39,AX39,AZ39,BB39,BD39,BF39,BH39) -> 32.2 | AI39: =MIN(AP39,AR39,AT39,AV39,AX39,AZ39,BB39,BD39,BF39,BH39) -> 32 | AJ39: =(AH39-D39)/D39 -> 0.073333333 | AK39: =AVERAGE(AQ39,AS39,AU39,AW39,AY39,BA39,BC39,BE39,BG39,BI39)/1000 -> 18.4032 | AL39: =AVERAGE(E39,G39,I39,K39,M39,O39,Q39,S39,U39,W39) -> 32 | AM39: =MIN(E39,G39,I39,K39,M39,O39,Q39,S39,U39,W39) -> 32 | AN39: =(AL39-D39)/D39 -> 0.066666667 | AO39: =AVERAGE(F39,H39,J39,L39,N39,P39,R39,T39,V39,X39)/1000 -> 22.2214 | AP39: 32 | AQ39: 14611 | AR39: 32 | AS39: 17651 | AT39: 32 | AU39: 21944 | AV39: 32 | AW39: 17350 | AX39: 34 | AY39: 15214 | AZ39: 32 | BA39: 19699 | BB39: 32 | BC39: 20042 | BD39: 32 | BE39: 17588 | BF39: 32 | BG39: 23200 | BH39: 32 | BI39: 16733
A40: S4-P13 | B40: 37 | C40: 4 | D40: 40 | E40: 40 | F40: 12 | G40: 40 | H40: 8 | I40: 40 | J40: 8 | K40: 40 | L40: 7 | M40: 40 | N40: 7 | O40: 40 | P40: 11 | Q40: 40 | R40: 7 | S40: 40 | T40: 6 | U40: 40 | V40: 7 | W40: 40 | X40: 7 | Y40: 40 | Z40: 40 | AA40: 40 | AB40: 0 | AC40: 9.61 | AD40: 40 | AE40: 40 | AF40: 0 | AG40: 0 | AH40: =AVERAGE(AP40,AR40,AT40,AV40,AX40,AZ40,BB40,BD40,BF40,BH40) -> 40 | AI40: =MIN(AP40,AR40,AT40,AV40,AX40,AZ40,BB40,BD40,BF40,BH40) -> 40 | AJ40: =(AH40-D40)/D40 -> 0 | AK40: =AVERAGE(AQ40,AS40,AU40,AW40,AY40,BA40,BC40,BE40,BG40,BI40)/1000 -> 0.0456 | AL40: =AVERAGE(E40,G40,I40,K40,M40,O40,Q40,S40,U40,W40) -> 40 | AM40: =MIN(E40,G40,I40,K40,M40,O40,Q40,S40,U40,W40) -> 40 | AN40: =(AL40-D40)/D40 -> 0 | AO40: =AVERAGE(F40,H40,J40,L40,N40,P40,R40,T40,V40,X40)/1000 -> 0.008 | AP40: 40 | AQ40: 67 | AR40: 40 | AS40: 56 | AT40: 40 | AU40: 37 | AV40: 40 | AW40: 27 | AX40: 40 | AY40: 33 | AZ40: 40 | BA40: 74 | BB40: 40 | BC40: 75 | BD40: 40 | BE40: 28 | BF40: 40 | BG40: 39 | BH40: 40 | BI40: 20
... A102: S16-P25 | B102: 96 | C102: 16 | D102: 120 | E102: 121 | F102: 265126 | G102: 121 | H102: 274743 | I102: 121 | J102: 278446 | K102: 121 | L102: 265196 | M102: 121 | N102: 268672 | O102: 121 | P102: 268858 | Q102: 121 | R102: 283530 | S102: 121 | T102: 271406 | U102: 121 | V102: 275232 | W102: 121 | X102: 261762 | Y102: 121 | Z102: 140.1 | AA102: 137 | AB102: 16.8 | AC102: 226.2 | AD102: 122.6 | AE102: 121 | AF102: 2.2 | AG102: 153.6 | AH102: =AVERAGE(AP102,AR102,AT102,AV102,AX102,AZ102,BB102,BD102,BF102,BH102) -> 124.1 | AI102: =MIN(AP102,AR102,AT102,AV102,AX102,AZ102,BB102,BD102,BF102,BH102) -> 123 | AJ102: =(AH102-D102)/D102 -> 0.034166667 | AK102: =AVERAGE(AQ102,AS102,AU102,AW102,AY102,BA102,BC102,BE102,BG102,BI102)/1000 -> 153.6 | AL102: =AVERAGE(E102,G102,I102,K102,M102,O102,Q102,S102,U102,W102) -> 121 | AM102: =MIN(E102,G102,I102,K102,M102,O102,Q102,S102,U102,W102) -> 121 | AN102: =(AL102-D102)/D102 -> 0.0083333333 | AO102: =AVERAGE(F102,H102,J102,L102,N102,P102,R102,T102,V102,X102)/1000 -> 271.2971 | AP102: 123 | AQ102: 153600 | AR102: 124 | AS102: 153600 | AT102: 125 | AU102: 153600 | AV102: 124 | AW102: 153600 | AX102: 125 | AY102: 153600 | AZ102: 124 | BA102: 153600 | BB102: 125 | BC102: 153600 | BD102: 123 | BE102: 153600 | BF102: 124 | BG102: 153600 | BH102: 124 | BI102: 153600
AB109: Average performance results
AB111: K | AC111: GA | AD111: TS | AE111: hPSOTS | AF111: SSPR
AB112: 2 | AC112: =AVERAGE(AB3:AB27) -> 4.308 | AD112: =AVERAGE(AF3:AF27) -> 4.308 | AE112: =AVERAGE(AJ3:AJ27)*100 -> 4.3084656
AB113: 4 | AC113: =AVERAGE(AB28:AB52) -> 8.152 | AD113: =AVERAGE(AF28:AF52) -> 9.808 | AE113: =AVERAGE(AJ28:AJ52)*100 -> 5.3108736 | AF113: =AVERAGE(AN28:AN52)*100 -> 3.3386081
AB114: 8 | AC114: =AVERAGE(AB53:AB77) -> 15.188 | AD114: =AVERAGE(AF53:AF77) -> 5.576 | AE114: =AVERAGE(AJ53:AJ77)*100 -> 5.5830779 | AF114: =AVERAGE(AN53:AN77)*100 -> 2.1371659
AB115: 16 | AC115: =AVERAGE(AB78:AB102) -> 17.796 | AD115: =AVERAGE(AF78:AF102) -> 4.168 | AE115: =AVERAGE(AJ78:AJ102)*100 -> 4.4891296 | AF115: =AVERAGE(AN78:AN102)*100 -> 1.8641887
AB118: Average time results
AB120: K | AC120: GA | AD120: TS | AE120: hPSOTS | AF120: SSPR
AB121: 2 | AC121: =AVERAGE(AC3:AC27) -> 2.736 | AD121: =AVERAGE(AG3:AG27) -> 0.0192 | AE121: =AVERAGE(AK3:AK27) -> 0.159184
AB122: 4 | AC122: =AVERAGE(AC28:AC52) -> 18.8092 | AD122: =AVERAGE(AG28:AG52) -> 8.0532 | AE122: =AVERAGE(AK28:AK52) -> 12.027636 | AF122: =AVERAGE(AO28:AO52) -> 9.328884
AB123: 8 | AC123: =AVERAGE(AC53:AC77) -> 120.6496 | AD123: =AVERAGE(AG53:AG77) -> 55.6576 | AE123: =AVERAGE(AK53:AK77) -> 70.321992 | AF123: =AVERAGE(AO53:AO77) -> 59.67616
...

Sheet Table2
A1: Instance | B1: LB | D1: Average makespan of the ten runs | I1: Best makespan among the ten runs
D2: GA | E2: TS | F2: hPSTS | G2: SS/PR | I2: GA | J2: TS | K2: hPSTS | L2: SS/PR
A3: ='Detailed results'!A28 -> S4-P1 | B3: ='Detailed results'!D28 -> 26 | D3: ='Detailed results'!Z28 -> 31.9 | E3: ='Detailed results'!AD28 -> 33 | F3: ='Detailed results'!AH28 -> 30.9 | G3: ='Detailed results'!AL28 -> 29.4 | I3: ='Detailed results'!AA28 -> 31 | J3: ='Detailed results'!AE28 -> 33 | K3: ='Detailed results'!AI28 -> 30 | L3: ='Detailed results'!AM28 -> 29
A4: ='Detailed results'!A29 -> S4-P2 | B4: ='Detailed results'!D29 -> 21 | D4: ='Detailed results'!Z29 -> 21 | E4: ='Detailed results'!AD29 -> 21 | F4: ='Detailed results'!AH29 -> 21 | G4: ='Detailed results'!AL29 -> 21 | I4: ='Detailed results'!AA29 -> 21 | J4: ='Detailed results'!AE29 -> 21 | K4: ='Detailed results'!AI29 -> 21 | L4: ='Detailed results'!AM29 -> 21
A5: ='Detailed results'!A30 -> S4-P3 | B5: ='Detailed results'!D30 -> 48 | D5: ='Detailed results'!Z30 -> 56.1 | E5: ='Detailed results'!AD30 -> 54 | F5: ='Detailed results'!AH30 -> 52.2 | G5: ='Detailed results'!AL30 -> 51 | I5: ='Detailed results'!AA30 -> 54 | J5: ='Detailed results'!AE30 -> 51 | K5: ='Detailed results'!AI30 -> 51 | L5: ='Detailed results'!AM30 -> 51
A6: ='Detailed results'!A31 -> S4-P4 | B6: ='Detailed results'!D31 -> 27 | D6: ='Detailed results'!Z31 -> 28.8 | E6: ='Detailed results'!AD31 -> 30 | F6: ='Detailed results'!AH31 -> 29.4 | G6: ='Detailed results'!AL31 -> 27 | I6: ='Detailed results'!AA31 -> 27 | J6: ='Detailed results'!AE31 -> 30 | K6: ='Detailed results'!AI31 -> 27 | L6: ='Detailed results'!AM31 -> 27
A7: ='Detailed results'!A32 -> S4-P5 | B7: ='Detailed results'!D32 -> 32 | D7: ='Detailed results'!Z32 -> 33.6 | E7: ='Detailed results'!AD32 -> 32 | F7: ='Detailed results'!AH32 -> 32 | G7: ='Detailed results'!AL32 -> 32 | I7: ='Detailed results'!AA32 -> 32 | J7: ='Detailed results'!AE32 -> 32 | K7: ='Detailed results'!AI32 -> 32 | L7: ='Detailed results'!AM32 -> 32
A8: ='Detailed results'!A33 -> S4-P6 | B8: ='Detailed results'!D33 -> 25 | D8: ='Detailed results'!Z33 -> 27.9 | E8: ='Detailed results'!AD33 -> 28.1 | F8: ='Detailed results'!AH33 -> 26 | G8: ='Detailed results'!AL33 -> 28 | I8: ='Detailed results'!AA33 -> 26 | J8: ='Detailed results'!AE33 -> 28 | K8: ='Detailed results'!AI33 -> 26 | L8: ='Detailed results'!AM33 -> 28
A9: ='Detailed results'!A34 -> S4-P7 | B9: ='Detailed results'!D34 -> 36 | D9: ='Detailed results'!Z34 -> 36 | E9: ='Detailed results'!AD34 -> 40 | F9: ='Detailed results'!AH34 -> 36 | G9: ='Detailed results'!AL34 -> 36 | I9: ='Detailed results'!AA34 -> 36 | J9: ='Detailed results'!AE34 -> 40 | K9: ='Detailed results'!AI34 -> 36 | L9: ='Detailed results'!AM34 -> 36
A10: ='Detailed results'!A35 -> S4-P8 | B10: ='Detailed results'!D35 -> 33 | D10: ='Detailed results'!Z35 -> 33 | E10: ='Detailed results'!AD35 -> 34 | F10: ='Detailed results'!AH35 -> 33 | G10: ='Detailed results'!AL35 -> 33 | I10: ='Detailed results'!AA35 -> 33 | J10: ='Detailed results'!AE35 -> 34 | K10: ='Detailed results'!AI35 -> 33 | L10: ='Detailed results'!AM35 -> 33
A11: ='Detailed results'!A36 -> S4-P9 | B11: ='Detailed results'!D36 -> 39 | D11: ='Detailed results'!Z36 -> 47.8 | E11: ='Detailed results'!AD36 -> 48 | F11: ='Detailed results'!AH36 -> 44.2 | G11: ='Detailed results'!AL36 -> 41.9 | I11: ='Detailed results'!AA36 -> 46 | J11: ='Detailed results'!AE36 -> 47 | K11: ='Detailed results'!AI36 -> 41 | L11: ='Detailed results'!AM36 -> 41
A12: ='Detailed results'!A37 -> S4-P10 | B12: ='Detailed results'!D37 -> 56 | D12: ='Detailed results'!Z37 -> 57.6 | E12: ='Detailed results'!AD37 -> 56 | F12: ='Detailed results'!AH37 -> 56 | G12: ='Detailed results'!AL37 -> 56 | I12: ='Detailed results'!AA37 -> 56 | J12: ='Detailed results'!AE37 -> 56 | K12: ='Detailed results'!AI37 -> 56 | L12: ='Detailed results'!AM37 -> 56
A13: ='Detailed results'!A38 -> S4-P11 | B13: ='Detailed results'!D38 -> 40 | D13: ='Detailed results'!Z38 -> 43.7 | E13: ='Detailed results'!AD38 -> 40.6 | F13: ='Detailed results'!AH38 -> 40.8 | G13: ='Detailed results'!AL38 -> 40 | I13: ='Detailed results'!AA38 -> 43 | J13: ='Detailed results'!AE38 -> 40 | K13: ='Detailed results'!AI38 -> 40 | L13: ='Detailed results'!AM38 -> 40
A14: ='Detailed results'!A39 -> S4-P12 | B14: ='Detailed results'!D39 -> 30 | D14: ='Detailed results'!Z39 -> 33 | E14: ='Detailed results'!AD39 -> 37.2 | F14: ='Detailed results'!AH39 -> 32.2 | G14: ='Detailed results'!AL39 -> 32 | I14: ='Detailed results'!AA39 -> 32 | J14: ='Detailed results'!AE39 -> 36 | K14: ='Detailed results'!AI39 -> 32 | L14: ='Detailed results'!AM39 -> 32
... A27: ='Detailed results'!A52 -> S4-P25 | B27: ='Detailed results'!D52 -> 21 | D27: ='Detailed results'!Z52 -> 21.9 | E27: ='Detailed results'!AD52 -> 23.5 | F27: ='Detailed results'!AH52 -> 22.9 | G27: ='Detailed results'!AL52 -> 21 | I27: ='Detailed results'!AA52 -> 21 | J27: ='Detailed results'!AE52 -> 22 | K27: ='Detailed results'!AI52 -> 21 | L27: ='Detailed results'!AM52 -> 21

Sheet Table3
A1: Instance | B1: LB | D1: Average makespan of the ten runs | I1: Best makespan among the ten runs
D2: GA | E2: TS | F2: hPSTS | G2: SS/PR | I2: GA | J2: TS | K2: hPSTS | L2: SS/PR
A3: ='Detailed results'!A53 -> S8-P1 | B3: ='Detailed results'!D53 -> 48 | D3: ='Detailed results'!Z53 -> 60.4 | E3: ='Detailed results'!AD53 -> 55.9 | F3: ='Detailed results'!AH53 -> 55.7 | G3: ='Detailed results'!AL53 -> 52 | I3: ='Detailed results'!AA53 -> 57 | J3: ='Detailed results'!AE53 -> 53 | K3: ='Detailed results'!AI53 -> 53 | L3: ='Detailed results'!AM53 -> 52
A4: ='Detailed results'!A54 -> S8-P2 | B4: ='Detailed results'!D54 -> 32 | D4: ='Detailed results'!Z54 -> 39.6 | E4: ='Detailed results'!AD54 -> 35 | F4: ='Detailed results'!AH54 -> 35.9 | G4: ='Detailed results'!AL54 -> 34.8 | I4: ='Detailed results'!AA54 -> 39 | J4: ='Detailed results'!AE54 -> 35 | K4: ='Detailed results'!AI54 -> 35 | L4: ='Detailed results'!AM54 -> 34
A5: ='Detailed results'!A55 -> S8-P3 | B5: ='Detailed results'!D55 -> 32 | D5: ='Detailed results'!Z55 -> 37.5 | E5: ='Detailed results'!AD55 -> 34.9 | F5: ='Detailed results'!AH55 -> 34.9 | G5: ='Detailed results'!AL55 -> 32.8 | I5: ='Detailed results'!AA55 -> 37 | J5: ='Detailed results'!AE55 -> 34 | K5: ='Detailed results'!AI55 -> 33 | L5: ='Detailed results'!AM55 -> 32
A6: ='Detailed results'!A56 -> S8-P4 | B6: ='Detailed results'!D56 -> 108 | D6: ='Detailed results'!Z56 -> 129.9 | E6: ='Detailed results'!AD56 -> 120.3 | F6: ='Detailed results'!AH56 -> 115.8 | G6: ='Detailed results'!AL56 -> 111.3 | I6: ='Detailed results'!AA56 -> 126 | J6: ='Detailed results'!AE56 -> 120 | K6: ='Detailed results'!AI56 -> 114 | L6: ='Detailed results'!AM56 -> 111
A7: ='Detailed results'!A57 -> S8-P5 | B7: ='Detailed results'!D57 -> 78 | D7: ='Detailed results'!Z57 -> 87.2 | E7: ='Detailed results'!AD57 -> 78 | F7: ='Detailed results'!AH57 -> 78 | G7: ='Detailed results'!AL57 -> 78 | I7: ='Detailed results'!AA57 -> 85 | J7: ='Detailed results'!AE57 -> 78 | K7: ='Detailed results'!AI57 -> 78 | L7: ='Detailed results'!AM57 -> 78
A8: ='Detailed results'!A58 -> S8-P6 | B8: ='Detailed results'!D58 -> 63 | D8: ='Detailed results'!Z58 -> 71.9 | E8: ='Detailed results'!AD58 -> 64.3 | F8: ='Detailed results'!AH58 -> 64 | G8: ='Detailed results'!AL58 -> 63 | I8: ='Detailed results'!AA58 -> 70 | J8: ='Detailed results'!AE58 -> 64 | K8: ='Detailed results'!AI58 -> 63 | L8: ='Detailed results'!AM58 -> 63
A9: ='Detailed results'!A59 -> S8-P7 | B9: ='Detailed results'!D59 -> 36 | D9: ='Detailed results'!Z59 -> 40.2 | E9: ='Detailed results'!AD59 -> 36.3 | F9: ='Detailed results'!AH59 -> 37.2 | G9: ='Detailed results'!AL59 -> 36 | I9: ='Detailed results'!AA59 -> 39 | J9: ='Detailed results'!AE59 -> 36 | K9: ='Detailed results'!AI59 -> 36 | L9: ='Detailed results'!AM59 -> 36
A10: ='Detailed results'!A60 -> S8-P8 | B10: ='Detailed results'!D60 -> 55 | D10: ='Detailed results'!Z60 -> 68.1 | E10: ='Detailed results'!AD60 -> 64.3 | F10: ='Detailed results'!AH60 -> 59.9 | G10: ='Detailed results'!AL60 -> 58 | I10: ='Detailed results'!AA60 -> 66 | J10: ='Detailed results'!AE60 -> 59 | K10: ='Detailed results'!AI60 -> 58 | L10: ='Detailed results'!AM60 -> 58
A11: ='Detailed results'!A61 -> S8-P9 | B11: ='Detailed results'!D61 -> 42 | D11: ='Detailed results'!Z61 -> 49.1 | E11: ='Detailed results'!AD61 -> 43.6 | F11: ='Detailed results'!AH61 -> 45.3 | G11: ='Detailed results'!AL61 -> 42.1 | I11: ='Detailed results'!AA61 -> 48 | J11: ='Detailed results'!AE61 -> 43 | K11: ='Detailed results'!AI61 -> 44 | L11: ='Detailed results'!AM61 -> 42
A12: ='Detailed results'!A62 -> S8-P10 | B12: ='Detailed results'!D62 -> 32 | D12: ='Detailed results'!Z62 -> 38.8 | E12: ='Detailed results'!AD62 -> 37.3 | F12: ='Detailed results'!AH62 -> 35.2 | G12: ='Detailed results'!AL62 -> 34 | I12: ='Detailed results'!AA62 -> 38 | J12: ='Detailed results'!AE62 -> 36 | K12: ='Detailed results'!AI62 -> 34 | L12: ='Detailed results'!AM62 -> 34
A13: ='Detailed results'!A63 -> S8-P11 | B13: ='Detailed results'!D63 -> 45 | D13: ='Detailed results'!Z63 -> 47.8 | E13: ='Detailed results'!AD63 -> 45 | F13: ='Detailed results'!AH63 -> 45 | G13: ='Detailed results'!AL63 -> 45 | I13: ='Detailed results'!AA63 -> 47 | J13: ='Detailed results'!AE63 -> 45 | K13: ='Detailed results'!AI63 -> 45 | L13: ='Detailed results'!AM63 -> 45
A14: ='Detailed results'!A64 -> S8-P12 | B14: ='Detailed results'!D64 -> 60 | D14: ='Detailed results'!Z64 -> 68.8 | E14: ='Detailed results'!AD64 -> 62.8 | F14: ='Detailed results'!AH64 -> 62.8 | G14: ='Detailed results'!AL64 -> 60.2 | I14: ='Detailed results'!AA64 -> 67 | J14: ='Detailed results'!AE64 -> 61 | K14: ='Detailed results'!AI64 -> 61 | L14: ='Detailed results'!AM64 -> 60
... A27: ='Detailed results'!A77 -> S8-P25 | B27: ='Detailed results'!D77 -> 35 | D27: ='Detailed results'!Z77 -> 41.6 | E27: ='Detailed results'!AD77 -> 37.2 | F27: ='Detailed results'!AH77 -> 38.5 | G27: ='Detailed results'!AL77 -> 36 | I27: ='Detailed results'!AA77 -> 40 | J27: ='Detailed results'!AE77 -> 36 | K27: ='Detailed results'!AI77 -> 38 | L27: ='Detailed results'!AM77 -> 36

Sheet Table4
A1: Instance | B1: LB | D1: Average makespan of the ten runs | I1: Best makespan among the ten runs
D2: GA | E2: TS | F2: hPSTS | G2: SS/PR | I2: GA | J2: TS | K2: hPSTS | L2: SS/PR
A3: ='Detailed results'!A78 -> S16-P1 | B3: ='Detailed results'!D78 -> 135 | D3: ='Detailed results'!Z78 -> 162.6 | E3: ='Detailed results'!AD78 -> 144.6 | F3: ='Detailed results'!AH78 -> 147.3 | G3: ='Detailed results'!AL78 -> 144 | I3: ='Detailed results'!AA78 -> 159 | J3: ='Detailed results'!AE78 -> 144 | K3: ='Detailed results'!AI78 -> 144 | L3: ='Detailed results'!AM78 -> 144
A4: ='Detailed results'!A79 -> S16-P2 | B4: ='Detailed results'!D79 -> 99 | D4: ='Detailed results'!Z79 -> 112.7 | E4: ='Detailed results'!AD79 -> 100 | F4: ='Detailed results'!AH79 -> 100.3 | G4: ='Detailed results'!AL79 -> 99 | I4: ='Detailed results'!AA79 -> 111 | J4: ='Detailed results'!AE79 -> 99 | K4: ='Detailed results'!AI79 -> 100 | L4: ='Detailed results'!AM79 -> 99
A5: ='Detailed results'!A80 -> S16-P3 | B5: ='Detailed results'!D80 -> 140 | D5: ='Detailed results'!Z80 -> 164.7 | E5: ='Detailed results'!AD80 -> 146.2 | F5: ='Detailed results'!AH80 -> 144.8 | G5: ='Detailed results'!AL80 -> 143 | I5: ='Detailed results'!AA80 -> 163 | J5: ='Detailed results'!AE80 -> 144 | K5: ='Detailed results'!AI80 -> 144 | L5: ='Detailed results'!AM80 -> 143
A6: ='Detailed results'!A81 -> S16-P4 | B6: ='Detailed results'!D81 -> 104 | D6: ='Detailed results'!Z81 -> 125.9 | E6: ='Detailed results'!AD81 -> 108.2 | F6: ='Detailed results'!AH81 -> 108.6 | G6: ='Detailed results'!AL81 -> 107.3 | I6: ='Detailed results'!AA81 -> 124 | J6: ='Detailed results'!AE81 -> 106 | K6: ='Detailed results'!AI81 -> 107 | L6: ='Detailed results'!AM81 -> 107
A7: ='Detailed results'!A82 -> S16-P5 | B7: ='Detailed results'!D82 -> 100 | D7: ='Detailed results'!Z82 -> 119.8 | E7: ='Detailed results'!AD82 -> 108.2 | F7: ='Detailed results'!AH82 -> 108.1 | G7: ='Detailed results'!AL82 -> 104 | I7: ='Detailed results'!AA82 -> 118 | J7: ='Detailed results'!AE82 -> 104 | K7: ='Detailed results'!AI82 -> 106 | L7: ='Detailed results'!AM82 -> 104
A8: ='Detailed results'!A83 -> S16-P6 | B8: ='Detailed results'!D83 -> 143 | D8: ='Detailed results'!Z83 -> 167.2 | E8: ='Detailed results'!AD83 -> 147.1 | F8: ='Detailed results'!AH83 -> 145.7 | G8: ='Detailed results'!AL83 -> 144 | I8: ='Detailed results'!AA83 -> 165 | J8: ='Detailed results'!AE83 -> 145 | K8: ='Detailed results'!AI83 -> 145 | L8: ='Detailed results'!AM83 -> 144
A9: ='Detailed results'!A84 -> S16-P7 | B9: ='Detailed results'!D84 -> 121 | D9: ='Detailed results'!Z84 -> 142.4 | E9: ='Detailed results'!AD84 -> 124.2 | F9: ='Detailed results'!AH84 -> 125.7 | G9: ='Detailed results'!AL84 -> 122.9 | I9: ='Detailed results'!AA84 -> 141 | J9: ='Detailed results'!AE84 -> 123 | K9: ='Detailed results'!AI84 -> 125 | L9: ='Detailed results'!AM84 -> 122
A10: ='Detailed results'!A85 -> S16-P8 | B10: ='Detailed results'!D85 -> 63 | D10: ='Detailed results'!Z85 -> 70.2 | E10: ='Detailed results'!AD85 -> 63 | F10: ='Detailed results'!AH85 -> 63.3 | G10: ='Detailed results'!AL85 -> 63 | I10: ='Detailed results'!AA85 -> 69 | J10: ='Detailed results'!AE85 -> 63 | K10: ='Detailed results'!AI85 -> 63 | L10: ='Detailed results'!AM85 -> 63
A11: ='Detailed results'!A86 -> S16-P9 | B11: ='Detailed results'!D86 -> 121 | D11: ='Detailed results'!Z86 -> 140.9 | E11: ='Detailed results'!AD86 -> 124.2 | F11: ='Detailed results'!AH86 -> 124.4 | G11: ='Detailed results'!AL86 -> 121.9 | I11: ='Detailed results'!AA86 -> 140 | J11: ='Detailed results'!AE86 -> 121 | K11: ='Detailed results'!AI86 -> 123 | L11: ='Detailed results'!AM86 -> 121
A12: ='Detailed results'!A87 -> S16-P10 | B12: ='Detailed results'!D87 -> 120 | D12: ='Detailed results'!Z87 -> 140.1 | E12: ='Detailed results'!AD87 -> 122.2 | F12: ='Detailed results'!AH87 -> 123.5 | G12: ='Detailed results'!AL87 -> 121 | I12: ='Detailed results'!AA87 -> 139 | J12: ='Detailed results'!AE87 -> 121 | K12: ='Detailed results'!AI87 -> 122 | L12: ='Detailed results'!AM87 -> 121
A13: ='Detailed results'!A88 -> S16-P11 | B13: ='Detailed results'!D88 -> 80 | D13: ='Detailed results'!Z88 -> 92.2 | E13: ='Detailed results'!AD88 -> 80 | F13: ='Detailed results'!AH88 -> 81.9 | G13: ='Detailed results'!AL88 -> 80 | I13: ='Detailed results'!AA88 -> 90 | J13: ='Detailed results'!AE88 -> 80 | K13: ='Detailed results'!AI88 -> 81 | L13: ='Detailed results'!AM88 -> 80
A14: ='Detailed results'!A89 -> S16-P12 | B14: ='Detailed results'!D89 -> 154 | D14: ='Detailed results'!Z89 -> 194.6 | E14: ='Detailed results'!AD89 -> 166.7 | F14: ='Detailed results'!AH89 -> 167.8 | G14: ='Detailed results'!AL89 -> 164 | I14: ='Detailed results'!AA89 -> 192 | J14: ='Detailed results'!AE89 -> 166 | K14: ='Detailed results'!AI89 -> 166 | L14: ='Detailed results'!AM89 -> 163
... A27: ='Detailed results'!A102 -> S16-P25 | B27: ='Detailed results'!D102 -> 120 | D27: ='Detailed results'!Z102 -> 140.1 | E27: ='Detailed results'!AD102 -> 122.6 | F27: ='Detailed results'!AH102 -> 124.1 | G27: ='Detailed results'!AL102 -> 121 | I27: ='Detailed results'!AA102 -> 137 | J27: ='Detailed results'!AE102 -> 121 | K27: ='Detailed results'!AI102 -> 123 | L27: ='Detailed results'!AM102 -> 121

Sheet Table5
B1: Average percentage deviation from LB | G1: Average computational time (Seconds)
A2: |W| | B2: GA | C2: TS | D2: hPSTS | E2: SS/PR | G2: GA | H2: TS | I2: hPSTS | J2: SS/PR
A3: 4 | B3: ='Detailed results'!AC113 -> 8.152 | C3: ='Detailed results'!AD113 -> 9.808 | D3: ='Detailed results'!AE113 -> 5.3108736 | E3: ='Detailed results'!AF113 -> 3.3386081 | G3: ='Detailed results'!AC122 -> 18.8092 | H3: ='Detailed results'!AD122 -> 8.0532 | I3: ='Detailed results'!AE122 -> 12.027636 | J3: ='Detailed results'!AF122*2.26 -> 21.083278
A4: 8 | B4: ='Detailed results'!AC114 -> 15.188 | C4: ='Detailed results'!AD114 -> 5.576 | D4: ='Detailed results'!AE114 -> 5.5830779 | E4: ='Detailed results'!AF114 -> 2.1371659 | G4: ='Detailed results'!AC123 -> 120.6496 | H4: ='Detailed results'!AD123 -> 55.6576 | I4: ='Detailed results'!AE123 -> 70.321992 | J4: ='Detailed results'!AF123*2.26 -> 134.86812
A5: 16 | B5: ='Detailed results'!AC115 -> 17.796 | C5: ='Detailed results'!AD115 -> 4.168 | D5: ='Detailed results'!AE115 -> 4.4891296 | E5: ='Detailed results'!AF115 -> 1.8641887 | G5: ='Detailed results'!AC124 -> 206.3592 | H5: ='Detailed results'!AD124 -> 120.8064 | I5: ='Detailed results'!AE124 -> 148.08054 | J5: ='Detailed results'!AF124*2.26 -> 469.93211
