Workbook

Sheet MOSP results
B1: 6 | C1: 6 | D1: 6 | E1: 6 | F1: 6 | G1: 6 | H1: 6 | I1: 6 | J1: 6 | K1: 6 | L1: 6 | M1: 6 | N1: 6 | O1: 6 | P1: 6 | Q1: 6 | R1: 6 | S1: 6 | T1: 6 | U1: 6 | V1: 6 | W1: 6 | X1: 6 | Y1: 6 | Z1: 6 | AA1: 6 | AB1: 6 | AC1: 6 | AD1: 6 | AE1: 6 | AF1: 6 | AG1: 6 | AH1: 6 | AI1: 6 | AJ1: 6 | AK1: 6 | AL1: 12 | AM1: 12 | AN1: 12 | AO1: 12 | AP1: 12 | AQ1: 12 | AR1: 12 | AS1: 12 | AT1: 12 | AU1: 12 | AV1: 12 | AW1: 12 | AX1: 12 | AY1: 12 | AZ1: 12 | BA1: 12 | BB1: 12 | BC1: 12 | BD1: 12 | BE1: 12 | BF1: 12 | BG1: 12 | BH1: 12 | BI1: 12 | BJ1: 12 | BK1: 12 | BL1: 12 | BM1: 12 | BN1: 12 | BO1: 12 | BP1: 12 | BQ1: 12 | BR1: 12 | BS1: 12 | BT1: 12 | BU1: 12 | BV1: 6 | BW1: 6 | BX1: 6 | BY1: 6 | BZ1: 6 | CA1: 6 | CB1: 6 | CC1: 6 | CD1: 6 | CE1: 6 | CF1: 6 | CG1: 6 | CH1: 6 | CI1: 6 | CJ1: 6 | CK1: 6 | CL1: 6 | CM1: 6 | CN1: 6 | CO1: 6 | CP1: 6 | CQ1: 6 | CR1: 6 | CS1: 6 | CT1: 6 | CU1: 6 | CV1: 6 | CW1: 6 | CX1: 6 | CY1: 6 | CZ1: 6 | DA1: 6 | DB1: 6 | DC1: 6 | DD1: 6 | DE1: 6 | DF1: 12 | DG1: 12 | DH1: 12 | DI1: 12 | DJ1: 12 | DK1: 12 | DL1: 12 | DM1: 12 | DN1: 12 | DO1: 12 | DP1: 12 | DQ1: 12 | DR1: 12 | DS1: 12 | DT1: 12 | DU1: 12 | DV1: 12 | DW1: 12 | DX1: 12 | DY1: 12 | DZ1: 12 | EA1: 12 | EB1: 12 | EC1: 12 | ED1: 12 | EE1: 12 | EF1: 12 | EG1: 12 | EH1: 12 | EI1: 12 | EJ1: 12 | EK1: 12 | EL1: 12 | EM1: 12 | EN1: 12 | EO1: 12 | EP1: 6 | EQ1: 6 | ER1: 6 | ES1: 6 | ET1: 6 | EU1: 6 | EV1: 6 | EW1: 6 | EX1: 6 | EY1: 6 | EZ1: 6 | FA1: 6 | FB1: 6 | FC1: 6 | FD1: 6 | FE1: 6 | FF1: 6 | FG1: 6 | FH1: 6 | FI1: 6 | FJ1: 6 | FK1: 6 | FL1: 6 | FM1: 6 | FN1: 6 | FO1: 6 | FP1: 6 | FQ1: 6 | FR1: 6 | FS1: 6 | FT1: 6 | FU1: 6 | FV1: 6 | FW1: 6 | FX1: 6 | FY1: 6 | FZ1: 12 | GA1: 12 | GB1: 12 | GC1: 12 | GD1: 12 | GE1: 12 | GF1: 12 | GG1: 12 | GH1: 12 | GI1: 12 | GJ1: 12 | GK1: 12 | GL1: 12 | GM1: 12 | GN1: 12 | GO1: 12 | GP1: 12 | GQ1: 12 | GR1: 12 | GS1: 12 | GT1: 12 | GU1: 12 | GV1: 12 | GW1: 12 | GX1: 12 | GY1: 12 | GZ1: 12 | HA1: 12 | HB1: 12 | HC1: 12 | HD1: 12 | HE1: 12 | HF1: 12 | HG1: 12 | HH1: 12 | HI1: 12 | HJ1: 6 | HK1: 6 | HL1: 6 | HM1: 6 | HN1: 6 | HO1: 6 | HP1: 6 | HQ1: 6 | HR1: 6 | HS1: 6 | HT1: 6 | HU1: 6 | HV1: 6 | HW1: 6 | HX1: 6 | HY1: 6 | HZ1: 6 | IA1: 6 | IB1: 6 | IC1: 6 | ID1: 6 | IE1: 6 | IF1: 6 | IG1: 6 | IH1: 6 | II1: 6 | IJ1: 6 | IK1: 6 | IL1: 6 | IM1: 6 | IN1: 6 | IO1: 6 | IP1: 6 | IQ1: 6 | IR1: 6 | IS1: 6 | IT1: 12 | IU1: 12 | IV1: 12 | IW1: 12 | IX1: 12 | IY1: 12 | IZ1: 12 | JA1: 12 | JB1: 12 | JC1: 12 | JD1: 12 | JE1: 12 | JF1: 12 | JG1: 12 | JH1: 12 | JI1: 12 | JJ1: 12 | JK1: 12 | JL1: 12 | JM1: 12 | JN1: 12 | JO1: 12 | JP1: 12 | JQ1: 12 | JR1: 12 | JS1: 12 | JT1: 12 | JU1: 12 | JV1: 12 | JW1: 12 | JX1: 12 | JY1: 12 | JZ1: 12 | KA1: 12 | KB1: 12 | KC1: 12 | KD1: 6 | KE1: 6 | KF1: 6 | KG1: 6 | KH1: 6 | KI1: 6 | KJ1: 6 | KK1: 6 | KL1: 6 | KM1: 6 | KN1: 6 | KO1: 6 | KP1: 6 | KQ1: 6 | KR1: 6 | KS1: 6 | KT1: 6 | KU1: 6 | KV1: 6 | KW1: 6 | KX1: 6 | KY1: 6 | KZ1: 6 | LA1: 6 | LB1: 6 | LC1: 6 | LD1: 6 | LE1: 6 | LF1: 6 | LG1: 6 | LH1: 6 | LI1: 6 | LJ1: 6 | LK1: 6 | LL1: 6 | LM1: 6 | LN1: 12 | LO1: 12 | LP1: 12 | LQ1: 12 | LR1: 12 | LS1: 12 | LT1: 12 | LU1: 12 | LV1: 12 | LW1: 12 | LX1: 12 | LY1: 12 | LZ1: 12 | MA1: 12 | MB1: 12 | MC1: 12 | MD1: 12 | ME1: 12 | MF1: 12 | MG1: 12 | MH1: 12 | MI1: 12 | MJ1: 12 | MK1: 12 | ML1: 12 | MM1: 12 | MN1: 12 | MO1: 12 | MP1: 12 | MQ1: 12 | MR1: 12 | MS1: 12 | MT1: 12 | MU1: 12 | MV1: 12 | MW1: 12
B2: 2 | C2: 2 | D2: 2 | E2: 2 | F2: 2 | G2: 2 | H2: 2 | I2: 2 | J2: 2 | K2: 2 | L2: 2 | M2: 2 | N2: 4 | O2: 4 | P2: 4 | Q2: 4 | R2: 4 | S2: 4 | T2: 4 | U2: 4 | V2: 4 | W2: 4 | X2: 4 | Y2: 4 | Z2: 6 | AA2: 6 | AB2: 6 | AC2: 6 | AD2: 6 | AE2: 6 | AF2: 6 | AG2: 6 | AH2: 6 | AI2: 6 | AJ2: 6 | AK2: 6 | AL2: 2 | AM2: 2 | AN2: 2 | AO2: 2 | AP2: 2 | AQ2: 2 | AR2: 2 | AS2: 2 | AT2: 2 | AU2: 2 | AV2: 2 | AW2: 2 | AX2: 4 | AY2: 4 | AZ2: 4 | BA2: 4 | BB2: 4 | BC2: 4 | BD2: 4 | BE2: 4 | BF2: 4 | BG2: 4 | BH2: 4 | BI2: 4 | BJ2: 6 | BK2: 6 | BL2: 6 | BM2: 6 | BN2: 6 | BO2: 6 | BP2: 6 | BQ2: 6 | BR2: 6 | BS2: 6 | BT2: 6 | BU2: 6 | BV2: 2 | BW2: 2 | BX2: 2 | BY2: 2 | BZ2: 2 | CA2: 2 | CB2: 2 | CC2: 2 | CD2: 2 | CE2: 2 | CF2: 2 | CG2: 2 | CH2: 4 | CI2: 4 | CJ2: 4 | CK2: 4 | CL2: 4 | CM2: 4 | CN2: 4 | CO2: 4 | CP2: 4 | CQ2: 4 | CR2: 4 | CS2: 4 | CT2: 6 | CU2: 6 | CV2: 6 | CW2: 6 | CX2: 6 | CY2: 6 | CZ2: 6 | DA2: 6 | DB2: 6 | DC2: 6 | DD2: 6 | DE2: 6 | DF2: 2 | DG2: 2 | DH2: 2 | DI2: 2 | DJ2: 2 | DK2: 2 | DL2: 2 | DM2: 2 | DN2: 2 | DO2: 2 | DP2: 2 | DQ2: 2 | DR2: 4 | DS2: 4 | DT2: 4 | DU2: 4 | DV2: 4 | DW2: 4 | DX2: 4 | DY2: 4 | DZ2: 4 | EA2: 4 | EB2: 4 | EC2: 4 | ED2: 6 | EE2: 6 | EF2: 6 | EG2: 6 | EH2: 6 | EI2: 6 | EJ2: 6 | EK2: 6 | EL2: 6 | EM2: 6 | EN2: 6 | EO2: 6 | EP2: 2 | EQ2: 2 | ER2: 2 | ES2: 2 | ET2: 2 | EU2: 2 | EV2: 2 | EW2: 2 | EX2: 2 | EY2: 2 | EZ2: 2 | FA2: 2 | FB2: 4 | FC2: 4 | FD2: 4 | FE2: 4 | FF2: 4 | FG2: 4 | FH2: 4 | FI2: 4 | FJ2: 4 | FK2: 4 | FL2: 4 | FM2: 4 | FN2: 6 | FO2: 6 | FP2: 6 | FQ2: 6 | FR2: 6 | FS2: 6 | FT2: 6 | FU2: 6 | FV2: 6 | FW2: 6 | FX2: 6 | FY2: 6 | FZ2: 2 | GA2: 2 | GB2: 2 | GC2: 2 | GD2: 2 | GE2: 2 | GF2: 2 | GG2: 2 | GH2: 2 | GI2: 2 | GJ2: 2 | GK2: 2 | GL2: 4 | GM2: 4 | GN2: 4 | GO2: 4 | GP2: 4 | GQ2: 4 | GR2: 4 | GS2: 4 | GT2: 4 | GU2: 4 | GV2: 4 | GW2: 4 | GX2: 6 | GY2: 6 | GZ2: 6 | HA2: 6 | HB2: 6 | HC2: 6 | HD2: 6 | HE2: 6 | HF2: 6 | HG2: 6 | HH2: 6 | HI2: 6 | HJ2: 2 | HK2: 2 | HL2: 2 | HM2: 2 | HN2: 2 | HO2: 2 | HP2: 2 | HQ2: 2 | HR2: 2 | HS2: 2 | HT2: 2 | HU2: 2 | HV2: 4 | HW2: 4 | HX2: 4 | HY2: 4 | HZ2: 4 | IA2: 4 | IB2: 4 | IC2: 4 | ID2: 4 | IE2: 4 | IF2: 4 | IG2: 4 | IH2: 6 | II2: 6 | IJ2: 6 | IK2: 6 | IL2: 6 | IM2: 6 | IN2: 6 | IO2: 6 | IP2: 6 | IQ2: 6 | IR2: 6 | IS2: 6 | IT2: 2 | IU2: 2 | IV2: 2 | IW2: 2 | IX2: 2 | IY2: 2 | IZ2: 2 | JA2: 2 | JB2: 2 | JC2: 2 | JD2: 2 | JE2: 2 | JF2: 4 | JG2: 4 | JH2: 4 | JI2: 4 | JJ2: 4 | JK2: 4 | JL2: 4 | JM2: 4 | JN2: 4 | JO2: 4 | JP2: 4 | JQ2: 4 | JR2: 6 | JS2: 6 | JT2: 6 | JU2: 6 | JV2: 6 | JW2: 6 | JX2: 6 | JY2: 6 | JZ2: 6 | KA2: 6 | KB2: 6 | KC2: 6 | KD2: 2 | KE2: 2 | KF2: 2 | KG2: 2 | KH2: 2 | KI2: 2 | KJ2: 2 | KK2: 2 | KL2: 2 | KM2: 2 | KN2: 2 | KO2: 2 | KP2: 4 | KQ2: 4 | KR2: 4 | KS2: 4 | KT2: 4 | KU2: 4 | KV2: 4 | KW2: 4 | KX2: 4 | KY2: 4 | KZ2: 4 | LA2: 4 | LB2: 6 | LC2: 6 | LD2: 6 | LE2: 6 | LF2: 6 | LG2: 6 | LH2: 6 | LI2: 6 | LJ2: 6 | LK2: 6 | LL2: 6 | LM2: 6 | LN2: 2 | LO2: 2 | LP2: 2 | LQ2: 2 | LR2: 2 | LS2: 2 | LT2: 2 | LU2: 2 | LV2: 2 | LW2: 2 | LX2: 2 | LY2: 2 | LZ2: 4 | MA2: 4 | MB2: 4 | MC2: 4 | MD2: 4 | ME2: 4 | MF2: 4 | MG2: 4 | MH2: 4 | MI2: 4 | MJ2: 4 | MK2: 4 | ML2: 6 | MM2: 6 | MN2: 6 | MO2: 6 | MP2: 6 | MQ2: 6 | MR2: 6 | MS2: 6 | MT2: 6 | MU2: 6 | MV2: 6 | MW2: 6
B3: 1 to 3 | C3: 1 to 3 | D3: 1 to 3 | E3: 1 to 3 | F3: 1 to 3 | G3: 1 to 3 | H3: 4 to 6 | I3: 4 to 6 | J3: 4 to 6 | K3: 4 to 6 | L3: 4 to 6 | M3: 4 to 6 | N3: 1 to 3 | O3: 1 to 3 | P3: 1 to 3 | Q3: 1 to 3 | R3: 1 to 3 | S3: 1 to 3 | T3: 4 to 6 | U3: 4 to 6 | V3: 4 to 6 | W3: 4 to 6 | X3: 4 to 6 | Y3: 4 to 6 | Z3: 1 to 3 | AA3: 1 to 3 | AB3: 1 to 3 | AC3: 1 to 3 | AD3: 1 to 3 | AE3: 1 to 3 | AF3: 4 to 6 | AG3: 4 to 6 | AH3: 4 to 6 | AI3: 4 to 6 | AJ3: 4 to 6 | AK3: 4 to 6 | AL3: 1 to 3 | AM3: 1 to 3 | AN3: 1 to 3 | AO3: 1 to 3 | AP3: 1 to 3 | AQ3: 1 to 3 | AR3: 4 to 6 | AS3: 4 to 6 | AT3: 4 to 6 | AU3: 4 to 6 | AV3: 4 to 6 | AW3: 4 to 6 | AX3: 1 to 3 | AY3: 1 to 3 | AZ3: 1 to 3 | BA3: 1 to 3 | BB3: 1 to 3 | BC3: 1 to 3 | BD3: 4 to 6 | BE3: 4 to 6 | BF3: 4 to 6 | BG3: 4 to 6 | BH3: 4 to 6 | BI3: 4 to 6 | BJ3: 1 to 3 | BK3: 1 to 3 | BL3: 1 to 3 | BM3: 1 to 3 | BN3: 1 to 3 | BO3: 1 to 3 | BP3: 4 to 6 | BQ3: 4 to 6 | BR3: 4 to 6 | BS3: 4 to 6 | BT3: 4 to 6 | BU3: 4 to 6 | BV3: 1 to 3 | BW3: 1 to 3 | BX3: 1 to 3 | BY3: 1 to 3 | BZ3: 1 to 3 | CA3: 1 to 3 | CB3: 4 to 6 | CC3: 4 to 6 | CD3: 4 to 6 | CE3: 4 to 6 | CF3: 4 to 6 | CG3: 4 to 6 | CH3: 1 to 3 | CI3: 1 to 3 | CJ3: 1 to 3 | CK3: 1 to 3 | CL3: 1 to 3 | CM3: 1 to 3 | CN3: 4 to 6 | CO3: 4 to 6 | CP3: 4 to 6 | CQ3: 4 to 6 | CR3: 4 to 6 | CS3: 4 to 6 | CT3: 1 to 3 | CU3: 1 to 3 | CV3: 1 to 3 | CW3: 1 to 3 | CX3: 1 to 3 | CY3: 1 to 3 | CZ3: 4 to 6 | DA3: 4 to 6 | DB3: 4 to 6 | DC3: 4 to 6 | DD3: 4 to 6 | DE3: 4 to 6 | DF3: 1 to 3 | DG3: 1 to 3 | DH3: 1 to 3 | DI3: 1 to 3 | DJ3: 1 to 3 | DK3: 1 to 3 | DL3: 4 to 6 | DM3: 4 to 6 | DN3: 4 to 6 | DO3: 4 to 6 | DP3: 4 to 6 | DQ3: 4 to 6 | DR3: 1 to 3 | DS3: 1 to 3 | DT3: 1 to 3 | DU3: 1 to 3 | DV3: 1 to 3 | DW3: 1 to 3 | DX3: 4 to 6 | DY3: 4 to 6 | DZ3: 4 to 6 | EA3: 4 to 6 | EB3: 4 to 6 | EC3: 4 to 6 | ED3: 1 to 3 | EE3: 1 to 3 | EF3: 1 to 3 | EG3: 1 to 3 | EH3: 1 to 3 | EI3: 1 to 3 | EJ3: 4 to 6 | EK3: 4 to 6 | EL3: 4 to 6 | EM3: 4 to 6 | EN3: 4 to 6 | EO3: 4 to 6 | EP3: 1 to 3 | EQ3: 1 to 3 | ER3: 1 to 3 | ES3: 1 to 3 | ET3: 1 to 3 | EU3: 1 to 3 | EV3: 4 to 6 | EW3: 4 to 6 | EX3: 4 to 6 | EY3: 4 to 6 | EZ3: 4 to 6 | FA3: 4 to 6 | FB3: 1 to 3 | FC3: 1 to 3 | FD3: 1 to 3 | FE3: 1 to 3 | FF3: 1 to 3 | FG3: 1 to 3 | FH3: 4 to 6 | FI3: 4 to 6 | FJ3: 4 to 6 | FK3: 4 to 6 | FL3: 4 to 6 | FM3: 4 to 6 | FN3: 1 to 3 | FO3: 1 to 3 | FP3: 1 to 3 | FQ3: 1 to 3 | FR3: 1 to 3 | FS3: 1 to 3 | FT3: 4 to 6 | FU3: 4 to 6 | FV3: 4 to 6 | FW3: 4 to 6 | FX3: 4 to 6 | FY3: 4 to 6 | FZ3: 1 to 3 | GA3: 1 to 3 | GB3: 1 to 3 | GC3: 1 to 3 | GD3: 1 to 3 | GE3: 1 to 3 | GF3: 4 to 6 | GG3: 4 to 6 | GH3: 4 to 6 | GI3: 4 to 6 | GJ3: 4 to 6 | GK3: 4 to 6 | GL3: 1 to 3 | GM3: 1 to 3 | GN3: 1 to 3 | GO3: 1 to 3 | GP3: 1 to 3 | GQ3: 1 to 3 | GR3: 4 to 6 | GS3: 4 to 6 | GT3: 4 to 6 | GU3: 4 to 6 | GV3: 4 to 6 | GW3: 4 to 6 | GX3: 1 to 3 | GY3: 1 to 3 | GZ3: 1 to 3 | HA3: 1 to 3 | HB3: 1 to 3 | HC3: 1 to 3 | HD3: 4 to 6 | HE3: 4 to 6 | HF3: 4 to 6 | HG3: 4 to 6 | HH3: 4 to 6 | HI3: 4 to 6 | HJ3: 1 to 3 | HK3: 1 to 3 | HL3: 1 to 3 | HM3: 1 to 3 | HN3: 1 to 3 | HO3: 1 to 3 | HP3: 4 to 6 | HQ3: 4 to 6 | HR3: 4 to 6 | HS3: 4 to 6 | HT3: 4 to 6 | HU3: 4 to 6 | HV3: 1 to 3 | HW3: 1 to 3 | HX3: 1 to 3 | HY3: 1 to 3 | HZ3: 1 to 3 | IA3: 1 to 3 | IB3: 4 to 6 | IC3: 4 to 6 | ID3: 4 to 6 | IE3: 4 to 6 | IF3: 4 to 6 | IG3: 4 to 6 | IH3: 1 to 3 | II3: 1 to 3 | IJ3: 1 to 3 | IK3: 1 to 3 | IL3: 1 to 3 | IM3: 1 to 3 | IN3: 4 to 6 | IO3: 4 to 6 | IP3: 4 to 6 | IQ3: 4 to 6 | IR3: 4 to 6 | IS3: 4 to 6 | IT3: 1 to 3 | IU3: 1 to 3 | IV3: 1 to 3 | IW3: 1 to 3 | IX3: 1 to 3 | IY3: 1 to 3 | IZ3: 4 to 6 | JA3: 4 to 6 | JB3: 4 to 6 | JC3: 4 to 6 | JD3: 4 to 6 | JE3: 4 to 6 | JF3: 1 to 3 | JG3: 1 to 3 | JH3: 1 to 3 | JI3: 1 to 3 | JJ3: 1 to 3 | JK3: 1 to 3 | JL3: 4 to 6 | JM3: 4 to 6 | JN3: 4 to 6 | JO3: 4 to 6 | JP3: 4 to 6 | JQ3: 4 to 6 | JR3: 1 to 3 | JS3: 1 to 3 | JT3: 1 to 3 | JU3: 1 to 3 | JV3: 1 to 3 | JW3: 1 to 3 | JX3: 4 to 6 | JY3: 4 to 6 | JZ3: 4 to 6 | KA3: 4 to 6 | KB3: 4 to 6 | KC3: 4 to 6 | KD3: 1 to 3 | KE3: 1 to 3 | KF3: 1 to 3 | KG3: 1 to 3 | KH3: 1 to 3 | KI3: 1 to 3 | KJ3: 4 to 6 | KK3: 4 to 6 | KL3: 4 to 6 | KM3: 4 to 6 | KN3: 4 to 6 | KO3: 4 to 6 | KP3: 1 to 3 | KQ3: 1 to 3 | KR3: 1 to 3 | KS3: 1 to 3 | KT3: 1 to 3 | KU3: 1 to 3 | KV3: 4 to 6 | KW3: 4 to 6 | KX3: 4 to 6 | KY3: 4 to 6 | KZ3: 4 to 6 | LA3: 4 to 6 | LB3: 1 to 3 | LC3: 1 to 3 | LD3: 1 to 3 | LE3: 1 to 3 | LF3: 1 to 3 | LG3: 1 to 3 | LH3: 4 to 6 | LI3: 4 to 6 | LJ3: 4 to 6 | LK3: 4 to 6 | LL3: 4 to 6 | LM3: 4 to 6 | LN3: 1 to 3 | LO3: 1 to 3 | LP3: 1 to 3 | LQ3: 1 to 3 | LR3: 1 to 3 | LS3: 1 to 3 | LT3: 4 to 6 | LU3: 4 to 6 | LV3: 4 to 6 | LW3: 4 to 6 | LX3: 4 to 6 | LY3: 4 to 6 | LZ3: 1 to 3 | MA3: 1 to 3 | MB3: 1 to 3 | MC3: 1 to 3 | MD3: 1 to 3 | ME3: 1 to 3 | MF3: 4 to 6 | MG3: 4 to 6 | MH3: 4 to 6 | MI3: 4 to 6 | MJ3: 4 to 6 | MK3: 4 to 6 | ML3: 1 to 3 | MM3: 1 to 3 | MN3: 1 to 3 | MO3: 1 to 3 | MP3: 1 to 3 | MQ3: 1 to 3 | MR3: 4 to 6 | MS3: 4 to 6 | MT3: 4 to 6 | MU3: 4 to 6 | MV3: 4 to 6 | MW3: 4 to 6
B4: 0.4 | C4: 0.4 | D4: 0.7 | E4: 0.7 | F4: 0.9 | G4: 0.9 | H4: 0.4 | I4: 0.4 | J4: 0.7 | K4: 0.7 | L4: 0.9 | M4: 0.9 | N4: 0.4 | O4: 0.4 | P4: 0.7 | Q4: 0.7 | R4: 0.9 | S4: 0.9 | T4: 0.4 | U4: 0.4 | V4: 0.7 | W4: 0.7 | X4: 0.9 | Y4: 0.9 | Z4: 0.4 | AA4: 0.4 | AB4: 0.7 | AC4: 0.7 | AD4: 0.9 | AE4: 0.9 | AF4: 0.4 | AG4: 0.4 | AH4: 0.7 | AI4: 0.7 | AJ4: 0.9 | AK4: 0.9 | AL4: 0.4 | AM4: 0.4 | AN4: 0.7 | AO4: 0.7 | AP4: 0.9 | AQ4: 0.9 | AR4: 0.4 | AS4: 0.4 | AT4: 0.7 | AU4: 0.7 | AV4: 0.9 | AW4: 0.9 | AX4: 0.4 | AY4: 0.4 | AZ4: 0.7 | BA4: 0.7 | BB4: 0.9 | BC4: 0.9 | BD4: 0.4 | BE4: 0.4 | BF4: 0.7 | BG4: 0.7 | BH4: 0.9 | BI4: 0.9 | BJ4: 0.4 | BK4: 0.4 | BL4: 0.7 | BM4: 0.7 | BN4: 0.9 | BO4: 0.9 | BP4: 0.4 | BQ4: 0.4 | BR4: 0.7 | BS4: 0.7 | BT4: 0.9 | BU4: 0.9 | BV4: 0.4 | BW4: 0.4 | BX4: 0.7 | BY4: 0.7 | BZ4: 0.9 | CA4: 0.9 | CB4: 0.4 | CC4: 0.4 | CD4: 0.7 | CE4: 0.7 | CF4: 0.9 | CG4: 0.9 | CH4: 0.4 | CI4: 0.4 | CJ4: 0.7 | CK4: 0.7 | CL4: 0.9 | CM4: 0.9 | CN4: 0.4 | CO4: 0.4 | CP4: 0.7 | CQ4: 0.7 | CR4: 0.9 | CS4: 0.9 | CT4: 0.4 | CU4: 0.4 | CV4: 0.7 | CW4: 0.7 | CX4: 0.9 | CY4: 0.9 | CZ4: 0.4 | DA4: 0.4 | DB4: 0.7 | DC4: 0.7 | DD4: 0.9 | DE4: 0.9 | DF4: 0.4 | DG4: 0.4 | DH4: 0.7 | DI4: 0.7 | DJ4: 0.9 | DK4: 0.9 | DL4: 0.4 | DM4: 0.4 | DN4: 0.7 | DO4: 0.7 | DP4: 0.9 | DQ4: 0.9 | DR4: 0.4 | DS4: 0.4 | DT4: 0.7 | DU4: 0.7 | DV4: 0.9 | DW4: 0.9 | DX4: 0.4 | DY4: 0.4 | DZ4: 0.7 | EA4: 0.7 | EB4: 0.9 | EC4: 0.9 | ED4: 0.4 | EE4: 0.4 | EF4: 0.7 | EG4: 0.7 | EH4: 0.9 | EI4: 0.9 | EJ4: 0.4 | EK4: 0.4 | EL4: 0.7 | EM4: 0.7 | EN4: 0.9 | EO4: 0.9 | EP4: 0.4 | EQ4: 0.4 | ER4: 0.7 | ES4: 0.7 | ET4: 0.9 | EU4: 0.9 | EV4: 0.4 | EW4: 0.4 | EX4: 0.7 | EY4: 0.7 | EZ4: 0.9 | FA4: 0.9 | FB4: 0.4 | FC4: 0.4 | FD4: 0.7 | FE4: 0.7 | FF4: 0.9 | FG4: 0.9 | FH4: 0.4 | FI4: 0.4 | FJ4: 0.7 | FK4: 0.7 | FL4: 0.9 | FM4: 0.9 | FN4: 0.4 | FO4: 0.4 | FP4: 0.7 | FQ4: 0.7 | FR4: 0.9 | FS4: 0.9 | FT4: 0.4 | FU4: 0.4 | FV4: 0.7 | FW4: 0.7 | FX4: 0.9 | FY4: 0.9 | FZ4: 0.4 | GA4: 0.4 | GB4: 0.7 | GC4: 0.7 | GD4: 0.9 | GE4: 0.9 | GF4: 0.4 | GG4: 0.4 | GH4: 0.7 | GI4: 0.7 | GJ4: 0.9 | GK4: 0.9 | GL4: 0.4 | GM4: 0.4 | GN4: 0.7 | GO4: 0.7 | GP4: 0.9 | GQ4: 0.9 | GR4: 0.4 | GS4: 0.4 | GT4: 0.7 | GU4: 0.7 | GV4: 0.9 | GW4: 0.9 | GX4: 0.4 | GY4: 0.4 | GZ4: 0.7 | HA4: 0.7 | HB4: 0.9 | HC4: 0.9 | HD4: 0.4 | HE4: 0.4 | HF4: 0.7 | HG4: 0.7 | HH4: 0.9 | HI4: 0.9 | HJ4: 0.4 | HK4: 0.4 | HL4: 0.7 | HM4: 0.7 | HN4: 0.9 | HO4: 0.9 | HP4: 0.4 | HQ4: 0.4 | HR4: 0.7 | HS4: 0.7 | HT4: 0.9 | HU4: 0.9 | HV4: 0.4 | HW4: 0.4 | HX4: 0.7 | HY4: 0.7 | HZ4: 0.9 | IA4: 0.9 | IB4: 0.4 | IC4: 0.4 | ID4: 0.7 | IE4: 0.7 | IF4: 0.9 | IG4: 0.9 | IH4: 0.4 | II4: 0.4 | IJ4: 0.7 | IK4: 0.7 | IL4: 0.9 | IM4: 0.9 | IN4: 0.4 | IO4: 0.4 | IP4: 0.7 | IQ4: 0.7 | IR4: 0.9 | IS4: 0.9 | IT4: 0.4 | IU4: 0.4 | IV4: 0.7 | IW4: 0.7 | IX4: 0.9 | IY4: 0.9 | IZ4: 0.4 | JA4: 0.4 | JB4: 0.7 | JC4: 0.7 | JD4: 0.9 | JE4: 0.9 | JF4: 0.4 | JG4: 0.4 | JH4: 0.7 | JI4: 0.7 | JJ4: 0.9 | JK4: 0.9 | JL4: 0.4 | JM4: 0.4 | JN4: 0.7 | JO4: 0.7 | JP4: 0.9 | JQ4: 0.9 | JR4: 0.4 | JS4: 0.4 | JT4: 0.7 | JU4: 0.7 | JV4: 0.9 | JW4: 0.9 | JX4: 0.4 | JY4: 0.4 | JZ4: 0.7 | KA4: 0.7 | KB4: 0.9 | KC4: 0.9 | KD4: 0.4 | KE4: 0.4 | KF4: 0.7 | KG4: 0.7 | KH4: 0.9 | KI4: 0.9 | KJ4: 0.4 | KK4: 0.4 | KL4: 0.7 | KM4: 0.7 | KN4: 0.9 | KO4: 0.9 | KP4: 0.4 | KQ4: 0.4 | KR4: 0.7 | KS4: 0.7 | KT4: 0.9 | KU4: 0.9 | KV4: 0.4 | KW4: 0.4 | KX4: 0.7 | KY4: 0.7 | KZ4: 0.9 | LA4: 0.9 | LB4: 0.4 | LC4: 0.4 | LD4: 0.7 | LE4: 0.7 | LF4: 0.9 | LG4: 0.9 | LH4: 0.4 | LI4: 0.4 | LJ4: 0.7 | LK4: 0.7 | LL4: 0.9 | LM4: 0.9 | LN4: 0.4 | LO4: 0.4 | LP4: 0.7 | LQ4: 0.7 | LR4: 0.9 | LS4: 0.9 | LT4: 0.4 | LU4: 0.4 | LV4: 0.7 | LW4: 0.7 | LX4: 0.9 | LY4: 0.9 | LZ4: 0.4 | MA4: 0.4 | MB4: 0.7 | MC4: 0.7 | MD4: 0.9 | ME4: 0.9 | MF4: 0.4 | MG4: 0.4 | MH4: 0.7 | MI4: 0.7 | MJ4: 0.9 | MK4: 0.9 | ML4: 0.4 | MM4: 0.4 | MN4: 0.7 | MO4: 0.7 | MP4: 0.9 | MQ4: 0.9 | MR4: 0.4 | MS4: 0.4 | MT4: 0.7 | MU4: 0.7 | MV4: 0.9 | MW4: 0.9
B5: 0.95 to 1.05 | C5: 0.75 to 1.25 | D5: 0.95 to 1.05 | E5: 0.75 to 1.25 | F5: 0.95 to 1.05 | G5: 0.75 to 1.25 | H5: 0.95 to 1.05 | I5: 0.75 to 1.25 | J5: 0.95 to 1.05 | K5: 0.75 to 1.25 | L5: 0.95 to 1.05 | M5: 0.75 to 1.25 | N5: 0.95 to 1.05 | O5: 0.75 to 1.25 | P5: 0.95 to 1.05 | Q5: 0.75 to 1.25 | R5: 0.95 to 1.05 | S5: 0.75 to 1.25 | T5: 0.95 to 1.05 | U5: 0.75 to 1.25 | V5: 0.95 to 1.05 | W5: 0.75 to 1.25 | X5: 0.95 to 1.05 | Y5: 0.75 to 1.25 | Z5: 0.95 to 1.05 | AA5: 0.75 to 1.25 | AB5: 0.95 to 1.05 | AC5: 0.75 to 1.25 | AD5: 0.95 to 1.05 | AE5: 0.75 to 1.25 | AF5: 0.95 to 1.05 | AG5: 0.75 to 1.25 | AH5: 0.95 to 1.05 | AI5: 0.75 to 1.25 | AJ5: 0.95 to 1.05 | AK5: 0.75 to 1.25 | AL5: 0.95 to 1.05 | AM5: 0.75 to 1.25 | AN5: 0.95 to 1.05 | AO5: 0.75 to 1.25 | AP5: 0.95 to 1.05 | AQ5: 0.75 to 1.25 | AR5: 0.95 to 1.05 | AS5: 0.75 to 1.25 | AT5: 0.95 to 1.05 | AU5: 0.75 to 1.25 | AV5: 0.95 to 1.05 | AW5: 0.75 to 1.25 | AX5: 0.95 to 1.05 | AY5: 0.75 to 1.25 | AZ5: 0.95 to 1.05 | BA5: 0.75 to 1.25 | BB5: 0.95 to 1.05 | BC5: 0.75 to 1.25 | BD5: 0.95 to 1.05 | BE5: 0.75 to 1.25 | BF5: 0.95 to 1.05 | BG5: 0.75 to 1.25 | BH5: 0.95 to 1.05 | BI5: 0.75 to 1.25 | BJ5: 0.95 to 1.05 | BK5: 0.75 to 1.25 | BL5: 0.95 to 1.05 | BM5: 0.75 to 1.25 | BN5: 0.95 to 1.05 | BO5: 0.75 to 1.25 | BP5: 0.95 to 1.05 | BQ5: 0.75 to 1.25 | BR5: 0.95 to 1.05 | BS5: 0.75 to 1.25 | BT5: 0.95 to 1.05 | BU5: 0.75 to 1.25 | BV5: 0.95 to 1.05 | BW5: 0.75 to 1.25 | BX5: 0.95 to 1.05 | BY5: 0.75 to 1.25 | BZ5: 0.95 to 1.05 | CA5: 0.75 to 1.25 | CB5: 0.95 to 1.05 | CC5: 0.75 to 1.25 | CD5: 0.95 to 1.05 | CE5: 0.75 to 1.25 | CF5: 0.95 to 1.05 | CG5: 0.75 to 1.25 | CH5: 0.95 to 1.05 | CI5: 0.75 to 1.25 | CJ5: 0.95 to 1.05 | CK5: 0.75 to 1.25 | CL5: 0.95 to 1.05 | CM5: 0.75 to 1.25 | CN5: 0.95 to 1.05 | CO5: 0.75 to 1.25 | CP5: 0.95 to 1.05 | CQ5: 0.75 to 1.25 | CR5: 0.95 to 1.05 | CS5: 0.75 to 1.25 | CT5: 0.95 to 1.05 | CU5: 0.75 to 1.25 | CV5: 0.95 to 1.05 | CW5: 0.75 to 1.25 | CX5: 0.95 to 1.05 | CY5: 0.75 to 1.25 | CZ5: 0.95 to 1.05 | DA5: 0.75 to 1.25 | DB5: 0.95 to 1.05 | DC5: 0.75 to 1.25 | DD5: 0.95 to 1.05 | DE5: 0.75 to 1.25 | DF5: 0.95 to 1.05 | DG5: 0.75 to 1.25 | DH5: 0.95 to 1.05 | DI5: 0.75 to 1.25 | DJ5: 0.95 to 1.05 | DK5: 0.75 to 1.25 | DL5: 0.95 to 1.05 | DM5: 0.75 to 1.25 | DN5: 0.95 to 1.05 | DO5: 0.75 to 1.25 | DP5: 0.95 to 1.05 | DQ5: 0.75 to 1.25 | DR5: 0.95 to 1.05 | DS5: 0.75 to 1.25 | DT5: 0.95 to 1.05 | DU5: 0.75 to 1.25 | DV5: 0.95 to 1.05 | DW5: 0.75 to 1.25 | DX5: 0.95 to 1.05 | DY5: 0.75 to 1.25 | DZ5: 0.95 to 1.05 | EA5: 0.75 to 1.25 | EB5: 0.95 to 1.05 | EC5: 0.75 to 1.25 | ED5: 0.95 to 1.05 | EE5: 0.75 to 1.25 | EF5: 0.95 to 1.05 | EG5: 0.75 to 1.25 | EH5: 0.95 to 1.05 | EI5: 0.75 to 1.25 | EJ5: 0.95 to 1.05 | EK5: 0.75 to 1.25 | EL5: 0.95 to 1.05 | EM5: 0.75 to 1.25 | EN5: 0.95 to 1.05 | EO5: 0.75 to 1.25 | EP5: 0.95 to 1.05 | EQ5: 0.75 to 1.25 | ER5: 0.95 to 1.05 | ES5: 0.75 to 1.25 | ET5: 0.95 to 1.05 | EU5: 0.75 to 1.25 | EV5: 0.95 to 1.05 | EW5: 0.75 to 1.25 | EX5: 0.95 to 1.05 | EY5: 0.75 to 1.25 | EZ5: 0.95 to 1.05 | FA5: 0.75 to 1.25 | FB5: 0.95 to 1.05 | FC5: 0.75 to 1.25 | FD5: 0.95 to 1.05 | FE5: 0.75 to 1.25 | FF5: 0.95 to 1.05 | FG5: 0.75 to 1.25 | FH5: 0.95 to 1.05 | FI5: 0.75 to 1.25 | FJ5: 0.95 to 1.05 | FK5: 0.75 to 1.25 | FL5: 0.95 to 1.05 | FM5: 0.75 to 1.25 | FN5: 0.95 to 1.05 | FO5: 0.75 to 1.25 | FP5: 0.95 to 1.05 | FQ5: 0.75 to 1.25 | FR5: 0.95 to 1.05 | FS5: 0.75 to 1.25 | FT5: 0.95 to 1.05 | FU5: 0.75 to 1.25 | FV5: 0.95 to 1.05 | FW5: 0.75 to 1.25 | FX5: 0.95 to 1.05 | FY5: 0.75 to 1.25 | FZ5: 0.95 to 1.05 | GA5: 0.75 to 1.25 | GB5: 0.95 to 1.05 | GC5: 0.75 to 1.25 | GD5: 0.95 to 1.05 | GE5: 0.75 to 1.25 | GF5: 0.95 to 1.05 | GG5: 0.75 to 1.25 | GH5: 0.95 to 1.05 | GI5: 0.75 to 1.25 | GJ5: 0.95 to 1.05 | GK5: 0.75 to 1.25 | GL5: 0.95 to 1.05 | GM5: 0.75 to 1.25 | GN5: 0.95 to 1.05 | GO5: 0.75 to 1.25 | GP5: 0.95 to 1.05 | GQ5: 0.75 to 1.25 | GR5: 0.95 to 1.05 | GS5: 0.75 to 1.25 | GT5: 0.95 to 1.05 | GU5: 0.75 to 1.25 | GV5: 0.95 to 1.05 | GW5: 0.75 to 1.25 | GX5: 0.95 to 1.05 | GY5: 0.75 to 1.25 | GZ5: 0.95 to 1.05 | HA5: 0.75 to 1.25 | HB5: 0.95 to 1.05 | HC5: 0.75 to 1.25 | HD5: 0.95 to 1.05 | HE5: 0.75 to 1.25 | HF5: 0.95 to 1.05 | HG5: 0.75 to 1.25 | HH5: 0.95 to 1.05 | HI5: 0.75 to 1.25 | HJ5: 0.95 to 1.05 | HK5: 0.75 to 1.25 | HL5: 0.95 to 1.05 | HM5: 0.75 to 1.25 | HN5: 0.95 to 1.05 | HO5: 0.75 to 1.25 | HP5: 0.95 to 1.05 | HQ5: 0.75 to 1.25 | HR5: 0.95 to 1.05 | HS5: 0.75 to 1.25 | HT5: 0.95 to 1.05 | HU5: 0.75 to 1.25 | HV5: 0.95 to 1.05 | HW5: 0.75 to 1.25 | HX5: 0.95 to 1.05 | HY5: 0.75 to 1.25 | HZ5: 0.95 to 1.05 | IA5: 0.75 to 1.25 | IB5: 0.95 to 1.05 | IC5: 0.75 to 1.25 | ID5: 0.95 to 1.05 | IE5: 0.75 to 1.25 | IF5: 0.95 to 1.05 | IG5: 0.75 to 1.25 | IH5: 0.95 to 1.05 | II5: 0.75 to 1.25 | IJ5: 0.95 to 1.05 | IK5: 0.75 to 1.25 | IL5: 0.95 to 1.05 | IM5: 0.75 to 1.25 | IN5: 0.95 to 1.05 | IO5: 0.75 to 1.25 | IP5: 0.95 to 1.05 | IQ5: 0.75 to 1.25 | IR5: 0.95 to 1.05 | IS5: 0.75 to 1.25 | IT5: 0.95 to 1.05 | IU5: 0.75 to 1.25 | IV5: 0.95 to 1.05 | IW5: 0.75 to 1.25 | IX5: 0.95 to 1.05 | IY5: 0.75 to 1.25 | IZ5: 0.95 to 1.05 | JA5: 0.75 to 1.25 | JB5: 0.95 to 1.05 | JC5: 0.75 to 1.25 | JD5: 0.95 to 1.05 | JE5: 0.75 to 1.25 | JF5: 0.95 to 1.05 | JG5: 0.75 to 1.25 | JH5: 0.95 to 1.05 | JI5: 0.75 to 1.25 | JJ5: 0.95 to 1.05 | JK5: 0.75 to 1.25 | JL5: 0.95 to 1.05 | JM5: 0.75 to 1.25 | JN5: 0.95 to 1.05 | JO5: 0.75 to 1.25 | JP5: 0.95 to 1.05 | JQ5: 0.75 to 1.25 | JR5: 0.95 to 1.05 | JS5: 0.75 to 1.25 | JT5: 0.95 to 1.05 | JU5: 0.75 to 1.25 | JV5: 0.95 to 1.05 | JW5: 0.75 to 1.25 | JX5: 0.95 to 1.05 | JY5: 0.75 to 1.25 | JZ5: 0.95 to 1.05 | KA5: 0.75 to 1.25 | KB5: 0.95 to 1.05 | KC5: 0.75 to 1.25 | KD5: 0.95 to 1.05 | KE5: 0.75 to 1.25 | KF5: 0.95 to 1.05 | KG5: 0.75 to 1.25 | KH5: 0.95 to 1.05 | KI5: 0.75 to 1.25 | KJ5: 0.95 to 1.05 | KK5: 0.75 to 1.25 | KL5: 0.95 to 1.05 | KM5: 0.75 to 1.25 | KN5: 0.95 to 1.05 | KO5: 0.75 to 1.25 | KP5: 0.95 to 1.05 | KQ5: 0.75 to 1.25 | KR5: 0.95 to 1.05 | KS5: 0.75 to 1.25 | KT5: 0.95 to 1.05 | KU5: 0.75 to 1.25 | KV5: 0.95 to 1.05 | KW5: 0.75 to 1.25 | KX5: 0.95 to 1.05 | KY5: 0.75 to 1.25 | KZ5: 0.95 to 1.05 | LA5: 0.75 to 1.25 | LB5: 0.95 to 1.05 | LC5: 0.75 to 1.25 | LD5: 0.95 to 1.05 | LE5: 0.75 to 1.25 | LF5: 0.95 to 1.05 | LG5: 0.75 to 1.25 | LH5: 0.95 to 1.05 | LI5: 0.75 to 1.25 | LJ5: 0.95 to 1.05 | LK5: 0.75 to 1.25 | LL5: 0.95 to 1.05 | LM5: 0.75 to 1.25 | LN5: 0.95 to 1.05 | LO5: 0.75 to 1.25 | LP5: 0.95 to 1.05 | LQ5: 0.75 to 1.25 | LR5: 0.95 to 1.05 | LS5: 0.75 to 1.25 | LT5: 0.95 to 1.05 | LU5: 0.75 to 1.25 | LV5: 0.95 to 1.05 | LW5: 0.75 to 1.25 | LX5: 0.95 to 1.05 | LY5: 0.75 to 1.25 | LZ5: 0.95 to 1.05 | MA5: 0.75 to 1.25 | MB5: 0.95 to 1.05 | MC5: 0.75 to 1.25 | MD5: 0.95 to 1.05 | ME5: 0.75 to 1.25 | MF5: 0.95 to 1.05 | MG5: 0.75 to 1.25 | MH5: 0.95 to 1.05 | MI5: 0.75 to 1.25 | MJ5: 0.95 to 1.05 | MK5: 0.75 to 1.25 | ML5: 0.95 to 1.05 | MM5: 0.75 to 1.25 | MN5: 0.95 to 1.05 | MO5: 0.75 to 1.25 | MP5: 0.95 to 1.05 | MQ5: 0.75 to 1.25 | MR5: 0.95 to 1.05 | MS5: 0.75 to 1.25 | MT5: 0.95 to 1.05 | MU5: 0.75 to 1.25 | MV5: 0.95 to 1.05 | MW5: 0.75 to 1.25
A6: Best RPD | B6: =MIN(B75:B104) -> 1.1494253 | C6: =MIN(C75:C104) -> 0 | D6: =MIN(D75:D104) -> 0.21186441 | E6: =MIN(E75:E104) -> 6.1926606 | F6: =MIN(F75:F104) -> 0 | G6: =MIN(G75:G104) -> 2.1032505 | H6: =MIN(H75:H104) -> 0 | I6: =MIN(I75:I104) -> 0 | ... MW6: =MIN(MW75:MW104) -> 5.6242274
A7: Worst RPD | B7: =MAX(B75:B104) -> 1.1494253 | C7: =MAX(C75:C104) -> 0 | D7: =MAX(D75:D104) -> 0.21186441 | E7: =MAX(E75:E104) -> 8.2568807 | F7: =MAX(F75:F104) -> 0 | G7: =MAX(G75:G104) -> 2.1032505 | H7: =MAX(H75:H104) -> 0 | I7: =MAX(I75:I104) -> 0 | ... MW7: =MAX(MW75:MW104) -> 7.354759
A8: Avg RPD | B8: =AVERAGE(B75:B104) -> 1.1494253 | C8: =AVERAGE(C75:C104) -> 0 | D8: =AVERAGE(D75:D104) -> 0.21186441 | E8: =AVERAGE(E75:E104) -> 7.0642202 | F8: =AVERAGE(F75:F104) -> 0 | G8: =AVERAGE(G75:G104) -> 2.1032505 | H8: =AVERAGE(H75:H104) -> 0 | I8: =AVERAGE(I75:I104) -> 0 | ... MW8: =AVERAGE(MW75:MW104) -> 6.5090647
A9: Avg time | B9: =AVERAGE(B43:B72) -> 0.4442 | C9: =AVERAGE(C43:C72) -> 6.6666667e-05 | D9: =AVERAGE(D43:D72) -> 0.75183333 | E9: =AVERAGE(E43:E72) -> 1.0213333 | F9: =AVERAGE(F43:F72) -> 0.0022333333 | G9: =AVERAGE(G43:G72) -> 1.5164667 | H9: =AVERAGE(H43:H72) -> 0.0016 | I9: =AVERAGE(I43:I72) -> 0.0020666667 | ... MW9: =AVERAGE(MW43:MW72) -> 82.7099 | MY9: =MAX(B9:MW9) -> 87.899267
A11: LB | B11: 435 | C11: 283 | D11: 472 | E11: 436 | F11: 591 | G11: 523 | H11: 1006 | I11: 973 | J11: 1067 | K11: 800 | L11: 1429 | M11: 900 | N11: 545 | O11: 482 | P11: 1026 | Q11: 1014 | R11: 1034 | S11: 884 | T11: 820 | U11: 904 | V11: 1035 | W11: 1080 | X11: 1290 | Y11: 920 | Z11: 1053 | AA11: 907 | AB11: 1160 | AC11: 1332 | AD11: 1834 | AE11: 1841 | AF11: 1075 | AG11: 1080 | AH11: 1830 | AI11: 1084 | AJ11: 2004 | AK11: 1230 | AL11: 741 | AM11: 665 | AN11: 1078 | AO11: 839 | AP11: 1370 | AQ11: 1288 | AR11: 2007 | AS11: 1538 | AT11: 2226 | AU11: 1704 | AV11: 2356 | AW11: 2211 | AX11: 1153 | AY11: 1458 | AZ11: 1706 | BA11: 1997 | BB11: 2656 | BC11: 2172 | BD11: 1743 | BE11: 1459 | BF11: 2516 | BG11: 2038 | BH11: 2483 | BI11: 2337 | BJ11: 1567 | BK11: 1912 | BL11: 2853 | BM11: 2200 | BN11: 3791 | BO11: 3397 | BP11: 2016 | BQ11: 1388 | BR11: 2652 | BS11: 2524 | BT11: 3346 | BU11: 2881 | BV11: 376 | BW11: 261 | BX11: 408 | BY11: 424 | BZ11: 595 | CA11: 548 | CB11: 553 | CC11: 682 | CD11: 1122 | CE11: 1098 | CF11: 915 | CG11: 1027 | CH11: 651 | CI11: 576 | CJ11: 1110 | CK11: 935 | CL11: 1120 | CM11: 900 | CN11: 750 | CO11: 785 | CP11: 1107 | CQ11: 1098 | CR11: 1395 | CS11: 1074 | CT11: 1032 | CU11: 838 | CV11: 1262 | CW11: 1125 | CX11: 1323 | CY11: 1511 | CZ11: 1175 | DA11: 865 | DB11: 1620 | DC11: 1261 | DD11: 1740 | DE11: 1321 | DF11: 700 | DG11: 640 | DH11: 1000 | DI11: 1087 | DJ11: 1277 | DK11: 1258 | DL11: 2037 | DM11: 1480 | DN11: 1939 | DO11: 1766 | DP11: 2670 | DQ11: 2006 | DR11: 1214 | DS11: 1150 | DT11: 1804 | DU11: 2031 | DV11: 2250 | DW11: 2458 | DX11: 1797 | DY11: 1635 | DZ11: 2279 | EA11: 1792 | EB11: 2700 | EC11: 2336 | ED11: 1455 | EE11: 1625 | EF11: 2916 | EG11: 2708 | EH11: 3782 | EI11: 3726 | EJ11: 2208 | EK11: 1479 | EL11: 3340 | EM11: 2409 | EN11: 3780 | EO11: 3066 | EP11: 432 | EQ11: 304 | ER11: 575 | ES11: 471 | ET11: 632 | EU11: 687 | EV11: 784 | EW11: 952 | EX11: 1171 | EY11: 826 | EZ11: 1061 | FA11: 1256 | FB11: 373 | FC11: 456 | FD11: 756 | FE11: 1101 | FF11: 1160 | FG11: 1074 | FH11: 614 | FI11: 648 | FJ11: 1084 | FK11: 921 | FL11: 1200 | FM11: 1217 | FN11: 832 | FO11: 536 | FP11: 1522 | FQ11: 1322 | FR11: 1760 | FS11: 1559 | FT11: 996 | FU11: 769 | FV11: 1310 | FW11: 1205 | FX11: 1590 | FY11: 1456 | FZ11: 552 | GA11: 679 | GB11: 1141 | GC11: 842 | GD11: 1342 | GE11: 1316 | GF11: 1587 | GG11: 1278 | GH11: 2105 | GI11: 1832 | GJ11: 2551 | GK11: 2178 | GL11: 1196 | GM11: 1228 | GN11: 2047 | GO11: 1933 | GP11: 2662 | GQ11: 2551 | GR11: 1961 | GS11: 1570 | GT11: 2235 | GU11: 2013 | GV11: 2754 | GW11: 2165 | GX11: 1752 | GY11: 1741 | GZ11: 3097 | HA11: 2846 | HB11: 3494 | HC11: 3864 | HD11: 2010 | HE11: 1659 | HF11: 3094 | HG11: 2706 | HH11: 3934 | HI11: 3272 | HJ11: 215 | HK11: 338 | HL11: 456 | HM11: 543 | HN11: 656 | HO11: 607 | HP11: 664 | HQ11: 740 | HR11: 1154 | HS11: 1027 | HT11: 1242 | HU11: 927 | HV11: 726 | HW11: 650 | HX11: 978 | HY11: 853 | HZ11: 690 | IA11: 1445 | IB11: 1183 | IC11: 948 | ID11: 1276 | IE11: 835 | IF11: 1364 | IG11: 1092 | IH11: 945 | II11: 855 | IJ11: 1271 | IK11: 1408 | IL11: 1787 | IM11: 1920 | IN11: 1159 | IO11: 932 | IP11: 1695 | IQ11: 1141 | IR11: 1728 | IS11: 1539 | IT11: 719 | IU11: 561 | IV11: 870 | IW11: 860 | IX11: 1252 | IY11: 1399 | IZ11: 1969 | JA11: 1200 | JB11: 1995 | JC11: 1756 | JD11: 2019 | JE11: 2029 | JF11: 1152 | JG11: 1181 | JH11: 2235 | JI11: 1875 | JJ11: 2630 | JK11: 2289 | JL11: 1849 | JM11: 1553 | JN11: 2516 | JO11: 1966 | JP11: 2645 | JQ11: 2129 | JR11: 1560 | JS11: 1538 | JT11: 2933 | JU11: 3157 | JV11: 3851 | JW11: 3420 | JX11: 1752 | JY11: 1521 | JZ11: 2994 | KA11: 2672 | KB11: 3604 | KC11: 3086 | KD11: 289 | KE11: 350 | KF11: 485 | KG11: 438 | KH11: 676 | KI11: 596 | KJ11: 810 | KK11: 862 | KL11: 1211 | KM11: 1021 | KN11: 1112 | KO11: 1291 | KP11: 440 | KQ11: 495 | KR11: 784 | KS11: 893 | KT11: 1192 | KU11: 1225 | KV11: 1011 | KW11: 998 | KX11: 1253 | KY11: 1049 | KZ11: 1365 | LA11: 936 | LB11: 830 | LC11: 967 | LD11: 1530 | LE11: 1189 | LF11: 1617 | LG11: 1499 | LH11: 1074 | LI11: 825 | LJ11: 1316 | LK11: 1240 | LL11: 1743 | LM11: 1659 | LN11: 579 | LO11: 711 | LP11: 972 | LQ11: 977 | LR11: 1184 | LS11: 1070 | LT11: 1422 | LU11: 1156 | LV11: 2309 | LW11: 1946 | LX11: 2240 | LY11: 2080 | LZ11: 1127 | MA11: 1552 | MB11: 2057 | MC11: 2080 | MD11: 2150 | ME11: 2499 | MF11: 1929 | MG11: 1385 | MH11: 2280 | MI11: 2416 | MJ11: 2463 | MK11: 2554 | ML11: 1804 | MM11: 2002 | MN11: 3004 | MO11: 2664 | MP11: 3811 | MQ11: 4104 | MR11: 2043 | MS11: 1719 | MT11: 2788 | MU11: 2633 | MV11: 3842 | MW11: 3236
A12: 1 | B12: 440 | C12: 283 | D12: 473 | E12: 465 | F12: 591 | G12: 534 | H12: 1006 | I12: 973 | J12: 1067 | K12: 800 | L12: 1429 | M12: 900 | N12: 553 | O12: 487 | P12: 1043 | Q12: 1014 | R12: 1040 | S12: 909 | T12: 820 | U12: 904 | V12: 1035 | W12: 1121 | X12: 1292 | Y12: 999 | Z12: 1056 | AA12: 913 | AB12: 1181 | AC12: 1346 | AD12: 1842 | AE12: 1841 | AF12: 1080 | AG12: 1123 | AH12: 1852 | AI12: 1137 | AJ12: 2017 | AK12: 1309 | AL12: 741 | AM12: 665 | AN12: 1108 | AO12: 839 | AP12: 1376 | AQ12: 1288 | AR12: 2007 | AS12: 1538 | AT12: 2226 | AU12: 1704 | AV12: 2356 | AW12: 2211 | AX12: 1153 | AY12: 1474 | AZ12: 1753 | BA12: 1997 | BB12: 2708 | BC12: 2223 | BD12: 1743 | BE12: 1459 | BF12: 2516 | BG12: 2038 | BH12: 2587 | BI12: 2500 | BJ12: 1571 | BK12: 1995 | BL12: 2853 | BM12: 2278 | BN12: 3865 | BO12: 3456 | BP12: 2057 | BQ12: 1388 | BR12: 2719 | BS12: 2651 | BT12: 3426 | BU12: 3020 | BV12: 381 | BW12: 261 | BX12: 413 | BY12: 434 | BZ12: 597 | CA12: 573 | CB12: 553 | CC12: 682 | CD12: 1122 | CE12: 1098 | CF12: 915 | CG12: 1027 | CH12: 657 | CI12: 576 | CJ12: 1137 | CK12: 979 | CL12: 1120 | CM12: 900 | CN12: 750 | CO12: 785 | CP12: 1107 | CQ12: 1098 | CR12: 1423 | CS12: 1143 | CT12: 1032 | CU12: 838 | CV12: 1262 | CW12: 1125 | CX12: 1323 | CY12: 1511 | CZ12: 1175 | DA12: 865 | DB12: 1643 | DC12: 1312 | DD12: 1754 | DE12: 1420 | DF12: 700 | DG12: 643 | DH12: 1000 | DI12: 1095 | DJ12: 1277 | DK12: 1296 | DL12: 2037 | DM12: 1480 | DN12: 1939 | DO12: 1766 | DP12: 2670 | DQ12: 2006 | DR12: 1214 | DS12: 1150 | DT12: 1830 | DU12: 2069 | DV12: 2250 | DW12: 2458 | DX12: 1797 | DY12: 1635 | DZ12: 2282 | EA12: 1851 | EB12: 2798 | EC12: 2516 | ED12: 1488 | EE12: 1625 | EF12: 2994 | EG12: 2765 | EH12: 3847 | EI12: 3737 | EJ12: 2227 | EK12: 1536 | EL12: 3390 | EM12: 2609 | EN12: 3827 | EO12: 3295 | EP12: 441 | EQ12: 304 | ER12: 585 | ES12: 471 | ET12: 640 | EU12: 694 | EV12: 784 | EW12: 952 | EX12: 1171 | EY12: 826 | EZ12: 1061 | FA12: 1256 | FB12: 373 | FC12: 470 | FD12: 771 | FE12: 1101 | FF12: 1180 | FG12: 1098 | FH12: 614 | FI12: 648 | FJ12: 1084 | FK12: 921 | FL12: 1221 | FM12: 1244 | FN12: 832 | FO12: 563 | FP12: 1522 | FQ12: 1332 | FR12: 1812 | FS12: 1559 | FT12: 1013 | FU12: 805 | FV12: 1332 | FW12: 1271 | FX12: 1620 | FY12: 1575 | FZ12: 561 | GA12: 679 | GB12: 1160 | GC12: 876 | GD12: 1342 | GE12: 1316 | GF12: 1587 | GG12: 1278 | GH12: 2105 | GI12: 1832 | GJ12: 2551 | GK12: 2178 | GL12: 1202 | GM12: 1268 | GN12: 2098 | GO12: 1976 | GP12: 2662 | GQ12: 2551 | GR12: 1961 | GS12: 1570 | GT12: 2262 | GU12: 2013 | GV12: 2890 | GW12: 2287 | GX12: 1754 | GY12: 1741 | GZ12: 3097 | HA12: 2888 | HB12: 3543 | HC12: 3864 | HD12: 2020 | HE12: 1756 | HF12: 3146 | HG12: 2879 | HH12: 3987 | HI12: 3417 | HJ12: 218 | HK12: 341 | HL12: 464 | HM12: 551 | HN12: 671 | HO12: 607 | HP12: 664 | HQ12: 740 | HR12: 1154 | HS12: 1027 | HT12: 1242 | HU12: 927 | HV12: 726 | HW12: 663 | HX12: 999 | HY12: 853 | HZ12: 694 | IA12: 1445 | IB12: 1183 | IC12: 948 | ID12: 1276 | IE12: 841 | IF12: 1394 | IG12: 1126 | IH12: 945 | II12: 886 | IJ12: 1279 | IK12: 1441 | IL12: 1787 | IM12: 1920 | IN12: 1159 | IO12: 932 | IP12: 1731 | IQ12: 1235 | IR12: 1742 | IS12: 1686 | IT12: 719 | IU12: 571 | IV12: 891 | IW12: 860 | IX12: 1259 | IY12: 1399 | IZ12: 1969 | JA12: 1200 | JB12: 1995 | JC12: 1756 | JD12: 2020 | JE12: 2029 | JF12: 1164 | JG12: 1181 | JH12: 2235 | JI12: 1875 | JJ12: 2630 | JK12: 2317 | JL12: 1849 | JM12: 1553 | JN12: 2516 | JO12: 2010 | JP12: 2761 | JQ12: 2347 | JR12: 1560 | JS12: 1603 | JT12: 2950 | JU12: 3157 | JV12: 3938 | JW12: 3421 | JX12: 1767 | JY12: 1550 | JZ12: 3035 | KA12: 2780 | KB12: 3706 | KC12: 3265 | KD12: 289 | KE12: 368 | KF12: 485 | KG12: 454 | KH12: 676 | KI12: 614 | KJ12: 810 | KK12: 862 | KL12: 1211 | KM12: 1021 | KN12: 1112 | KO12: 1291 | KP12: 440 | KQ12: 522 | KR12: 786 | KS12: 908 | KT12: 1192 | KU12: 1225 | KV12: 1011 | KW12: 998 | KX12: 1253 | KY12: 1049 | KZ12: 1395 | LA12: 1014 | LB12: 850 | LC12: 967 | LD12: 1536 | LE12: 1197 | LF12: 1617 | LG12: 1499 | LH12: 1074 | LI12: 848 | LJ12: 1343 | LK12: 1281 | LL12: 1771 | LM12: 1751 | LN12: 579 | LO12: 711 | LP12: 1002 | LQ12: 981 | LR12: 1195 | LS12: 1104 | LT12: 1422 | LU12: 1156 | LV12: 2309 | LW12: 1946 | LX12: 2240 | LY12: 2080 | LZ12: 1147 | MA12: 1552 | MB12: 2104 | MC12: 2080 | MD12: 2171 | ME12: 2499 | MF12: 1929 | MG12: 1385 | MH12: 2319 | MI12: 2416 | MJ12: 2584 | MK12: 2644 | ML12: 1833 | MM12: 2002 | MN12: 3026 | MO12: 2760 | MP12: 3811 | MQ12: 4104 | MR12: 2073 | MS12: 1719 | MT12: 2844 | MU12: 2740 | MV12: 3913 | MW12: 3435
A13: 2 | B13: 440 | C13: 283 | D13: 473 | E13: 470 | F13: 591 | G13: 534 | H13: 1006 | I13: 973 | J13: 1067 | K13: 800 | L13: 1429 | M13: 900 | N13: 553 | O13: 487 | P13: 1043 | Q13: 1014 | R13: 1041 | S13: 907 | T13: 820 | U13: 904 | V13: 1035 | W13: 1110 | X13: 1295 | Y13: 1000 | Z13: 1056 | AA13: 913 | AB13: 1180 | AC13: 1337 | AD13: 1845 | AE13: 1841 | AF13: 1080 | AG13: 1123 | AH13: 1853 | AI13: 1149 | AJ13: 2017 | AK13: 1301 | AL13: 741 | AM13: 665 | AN13: 1109 | AO13: 839 | AP13: 1376 | AQ13: 1288 | AR13: 2007 | AS13: 1538 | AT13: 2226 | AU13: 1704 | AV13: 2356 | AW13: 2211 | AX13: 1153 | AY13: 1478 | AZ13: 1751 | BA13: 1997 | BB13: 2702 | BC13: 2233 | BD13: 1743 | BE13: 1459 | BF13: 2516 | BG13: 2038 | BH13: 2587 | BI13: 2491 | BJ13: 1572 | BK13: 1972 | BL13: 2853 | BM13: 2288 | BN13: 3866 | BO13: 3462 | BP13: 2060 | BQ13: 1388 | BR13: 2712 | BS13: 2657 | BT13: 3437 | BU13: 3051 | BV13: 381 | BW13: 261 | BX13: 413 | BY13: 434 | BZ13: 597 | CA13: 573 | CB13: 553 | CC13: 682 | CD13: 1122 | CE13: 1098 | CF13: 915 | CG13: 1027 | CH13: 656 | CI13: 576 | CJ13: 1137 | CK13: 971 | CL13: 1120 | CM13: 900 | CN13: 750 | CO13: 785 | CP13: 1107 | CQ13: 1098 | CR13: 1427 | CS13: 1124 | CT13: 1032 | CU13: 838 | CV13: 1262 | CW13: 1125 | CX13: 1323 | CY13: 1511 | CZ13: 1175 | DA13: 865 | DB13: 1641 | DC13: 1326 | DD13: 1756 | DE13: 1432 | DF13: 700 | DG13: 643 | DH13: 1000 | DI13: 1087 | DJ13: 1277 | DK13: 1289 | DL13: 2037 | DM13: 1480 | DN13: 1939 | DO13: 1766 | DP13: 2670 | DQ13: 2006 | DR13: 1214 | DS13: 1150 | DT13: 1832 | DU13: 2071 | DV13: 2250 | DW13: 2458 | DX13: 1797 | DY13: 1635 | DZ13: 2284 | EA13: 1844 | EB13: 2792 | EC13: 2458 | ED13: 1483 | EE13: 1625 | EF13: 3003 | EG13: 2767 | EH13: 3848 | EI13: 3758 | EJ13: 2229 | EK13: 1512 | EL13: 3391 | EM13: 2612 | EN13: 3836 | EO13: 3276 | EP13: 441 | EQ13: 304 | ER13: 585 | ES13: 471 | ET13: 640 | EU13: 700 | EV13: 784 | EW13: 952 | EX13: 1171 | EY13: 826 | EZ13: 1061 | FA13: 1256 | FB13: 373 | FC13: 470 | FD13: 771 | FE13: 1101 | FF13: 1179 | FG13: 1094 | FH13: 614 | FI13: 648 | FJ13: 1084 | FK13: 921 | FL13: 1221 | FM13: 1255 | FN13: 832 | FO13: 563 | FP13: 1522 | FQ13: 1334 | FR13: 1809 | FS13: 1559 | FT13: 1013 | FU13: 805 | FV13: 1330 | FW13: 1271 | FX13: 1619 | FY13: 1573 | FZ13: 561 | GA13: 679 | GB13: 1163 | GC13: 881 | GD13: 1342 | GE13: 1316 | GF13: 1587 | GG13: 1278 | GH13: 2105 | GI13: 1832 | GJ13: 2551 | GK13: 2178 | GL13: 1202 | GM13: 1261 | GN13: 2097 | GO13: 1979 | GP13: 2662 | GQ13: 2551 | GR13: 1961 | GS13: 1570 | GT13: 2263 | GU13: 2013 | GV13: 2929 | GW13: 2263 | GX13: 1757 | GY13: 1741 | GZ13: 3097 | HA13: 2891 | HB13: 3542 | HC13: 3864 | HD13: 2021 | HE13: 1755 | HF13: 3137 | HG13: 2863 | HH13: 3984 | HI13: 3418 | HJ13: 218 | HK13: 341 | HL13: 464 | HM13: 543 | HN13: 671 | HO13: 607 | HP13: 664 | HQ13: 740 | HR13: 1154 | HS13: 1027 | HT13: 1242 | HU13: 927 | HV13: 726 | HW13: 663 | HX13: 999 | HY13: 853 | HZ13: 695 | IA13: 1445 | IB13: 1183 | IC13: 948 | ID13: 1276 | IE13: 857 | IF13: 1395 | IG13: 1135 | IH13: 945 | II13: 886 | IJ13: 1277 | IK13: 1443 | IL13: 1787 | IM13: 1920 | IN13: 1159 | IO13: 932 | IP13: 1731 | IQ13: 1236 | IR13: 1746 | IS13: 1679 | IT13: 719 | IU13: 571 | IV13: 894 | IW13: 860 | IX13: 1257 | IY13: 1399 | IZ13: 1969 | JA13: 1200 | JB13: 1995 | JC13: 1756 | JD13: 2019 | JE13: 2029 | JF13: 1164 | JG13: 1181 | JH13: 2235 | JI13: 1875 | JJ13: 2630 | JK13: 2309 | JL13: 1849 | JM13: 1553 | JN13: 2518 | JO13: 1996 | JP13: 2762 | JQ13: 2342 | JR13: 1560 | JS13: 1596 | JT13: 2949 | JU13: 3157 | JV13: 3936 | JW13: 3420 | JX13: 1774 | JY13: 1569 | JZ13: 3037 | KA13: 2781 | KB13: 3706 | KC13: 3282 | KD13: 289 | KE13: 368 | KF13: 485 | KG13: 456 | KH13: 677 | KI13: 629 | KJ13: 810 | KK13: 862 | KL13: 1211 | KM13: 1021 | KN13: 1112 | KO13: 1291 | KP13: 440 | KQ13: 522 | KR13: 786 | KS13: 908 | KT13: 1192 | KU13: 1225 | KV13: 1011 | KW13: 998 | KX13: 1253 | KY13: 1049 | KZ13: 1397 | LA13: 1003 | LB13: 850 | LC13: 967 | LD13: 1537 | LE13: 1197 | LF13: 1617 | LG13: 1499 | LH13: 1074 | LI13: 848 | LJ13: 1342 | LK13: 1281 | LL13: 1773 | LM13: 1742 | LN13: 579 | LO13: 711 | LP13: 1005 | LQ13: 981 | LR13: 1199 | LS13: 1117 | LT13: 1422 | LU13: 1156 | LV13: 2309 | LW13: 1946 | LX13: 2240 | LY13: 2080 | LZ13: 1147 | MA13: 1552 | MB13: 2100 | MC13: 2080 | MD13: 2170 | ME13: 2499 | MF13: 1929 | MG13: 1385 | MH13: 2324 | MI13: 2416 | MJ13: 2595 | MK13: 2632 | ML13: 1831 | MM13: 2002 | MN13: 3023 | MO13: 2769 | MP13: 3811 | MQ13: 4104 | MR13: 2067 | MS13: 1719 | MT13: 2851 | MU13: 2729 | MV13: 3911 | MW13: 3461
A14: 3 | B14: 440 | C14: 283 | D14: 473 | E14: 463 | F14: 591 | G14: 534 | H14: 1006 | I14: 973 | J14: 1067 | K14: 800 | L14: 1429 | M14: 900 | N14: 553 | O14: 487 | P14: 1042 | Q14: 1014 | R14: 1040 | S14: 909 | T14: 820 | U14: 904 | V14: 1035 | W14: 1121 | X14: 1294 | Y14: 1000 | Z14: 1056 | AA14: 913 | AB14: 1180 | AC14: 1337 | AD14: 1846 | AE14: 1841 | AF14: 1080 | AG14: 1124 | AH14: 1850 | AI14: 1139 | AJ14: 2017 | AK14: 1307 | AL14: 741 | AM14: 665 | AN14: 1108 | AO14: 839 | AP14: 1374 | AQ14: 1288 | AR14: 2007 | AS14: 1538 | AT14: 2226 | AU14: 1704 | AV14: 2356 | AW14: 2211 | AX14: 1153 | AY14: 1474 | AZ14: 1751 | BA14: 1997 | BB14: 2710 | BC14: 2226 | BD14: 1743 | BE14: 1459 | BF14: 2516 | BG14: 2039 | BH14: 2590 | BI14: 2484 | BJ14: 1577 | BK14: 1983 | BL14: 2853 | BM14: 2287 | BN14: 3861 | BO14: 3435 | BP14: 2059 | BQ14: 1388 | BR14: 2711 | BS14: 2671 | BT14: 3438 | BU14: 3044 | BV14: 381 | BW14: 261 | BX14: 413 | BY14: 434 | BZ14: 596 | CA14: 573 | CB14: 553 | CC14: 682 | CD14: 1122 | CE14: 1098 | CF14: 915 | CG14: 1027 | CH14: 656 | CI14: 576 | CJ14: 1137 | CK14: 981 | CL14: 1120 | CM14: 900 | CN14: 750 | CO14: 785 | CP14: 1107 | CQ14: 1098 | CR14: 1428 | CS14: 1129 | CT14: 1032 | CU14: 838 | CV14: 1262 | CW14: 1125 | CX14: 1323 | CY14: 1511 | CZ14: 1175 | DA14: 865 | DB14: 1641 | DC14: 1327 | DD14: 1754 | DE14: 1410 | DF14: 700 | DG14: 644 | DH14: 1000 | DI14: 1094 | DJ14: 1277 | DK14: 1286 | DL14: 2037 | DM14: 1480 | DN14: 1939 | DO14: 1766 | DP14: 2670 | DQ14: 2006 | DR14: 1214 | DS14: 1150 | DT14: 1833 | DU14: 2064 | DV14: 2250 | DW14: 2458 | DX14: 1797 | DY14: 1635 | DZ14: 2283 | EA14: 1837 | EB14: 2781 | EC14: 2505 | ED14: 1485 | EE14: 1625 | EF14: 3005 | EG14: 2775 | EH14: 3843 | EI14: 3738 | EJ14: 2225 | EK14: 1524 | EL14: 3391 | EM14: 2598 | EN14: 3845 | EO14: 3287 | EP14: 441 | EQ14: 304 | ER14: 585 | ES14: 471 | ET14: 640 | EU14: 694 | EV14: 784 | EW14: 952 | EX14: 1171 | EY14: 826 | EZ14: 1061 | FA14: 1256 | FB14: 373 | FC14: 470 | FD14: 771 | FE14: 1101 | FF14: 1179 | FG14: 1094 | FH14: 614 | FI14: 648 | FJ14: 1084 | FK14: 921 | FL14: 1224 | FM14: 1262 | FN14: 832 | FO14: 563 | FP14: 1522 | FQ14: 1328 | FR14: 1811 | FS14: 1559 | FT14: 1014 | FU14: 805 | FV14: 1333 | FW14: 1271 | FX14: 1620 | FY14: 1574 | FZ14: 561 | GA14: 679 | GB14: 1167 | GC14: 874 | GD14: 1342 | GE14: 1316 | GF14: 1587 | GG14: 1278 | GH14: 2105 | GI14: 1832 | GJ14: 2551 | GK14: 2178 | GL14: 1201 | GM14: 1267 | GN14: 2095 | GO14: 1976 | GP14: 2662 | GQ14: 2551 | GR14: 1961 | GS14: 1570 | GT14: 2259 | GU14: 2013 | GV14: 2917 | GW14: 2276 | GX14: 1754 | GY14: 1741 | GZ14: 3097 | HA14: 2881 | HB14: 3542 | HC14: 3864 | HD14: 2022 | HE14: 1759 | HF14: 3148 | HG14: 2868 | HH14: 3967 | HI14: 3427 | HJ14: 218 | HK14: 341 | HL14: 464 | HM14: 543 | HN14: 671 | HO14: 607 | HP14: 664 | HQ14: 740 | HR14: 1154 | HS14: 1027 | HT14: 1242 | HU14: 927 | HV14: 726 | HW14: 663 | HX14: 999 | HY14: 853 | HZ14: 692 | IA14: 1445 | IB14: 1183 | IC14: 948 | ID14: 1276 | IE14: 841 | IF14: 1393 | IG14: 1131 | IH14: 945 | II14: 888 | IJ14: 1275 | IK14: 1434 | IL14: 1787 | IM14: 1920 | IN14: 1159 | IO14: 932 | IP14: 1727 | IQ14: 1219 | IR14: 1740 | IS14: 1701 | IT14: 719 | IU14: 571 | IV14: 892 | IW14: 860 | IX14: 1256 | IY14: 1399 | IZ14: 1969 | JA14: 1200 | JB14: 1995 | JC14: 1756 | JD14: 2020 | JE14: 2029 | JF14: 1164 | JG14: 1181 | JH14: 2235 | JI14: 1875 | JJ14: 2630 | JK14: 2314 | JL14: 1849 | JM14: 1553 | JN14: 2519 | JO14: 1991 | JP14: 2759 | JQ14: 2343 | JR14: 1560 | JS14: 1591 | JT14: 2951 | JU14: 3157 | JV14: 3932 | JW14: 3420 | JX14: 1772 | JY14: 1546 | JZ14: 3034 | KA14: 2767 | KB14: 3703 | KC14: 3265 | KD14: 289 | KE14: 368 | KF14: 485 | KG14: 452 | KH14: 677 | KI14: 626 | KJ14: 810 | KK14: 862 | KL14: 1211 | KM14: 1021 | KN14: 1112 | KO14: 1291 | KP14: 440 | KQ14: 522 | KR14: 786 | KS14: 908 | KT14: 1192 | KU14: 1225 | KV14: 1011 | KW14: 998 | KX14: 1253 | KY14: 1049 | KZ14: 1394 | LA14: 1012 | LB14: 850 | LC14: 967 | LD14: 1538 | LE14: 1193 | LF14: 1617 | LG14: 1499 | LH14: 1074 | LI14: 848 | LJ14: 1345 | LK14: 1295 | LL14: 1773 | LM14: 1755 | LN14: 579 | LO14: 711 | LP14: 999 | LQ14: 977 | LR14: 1200 | LS14: 1104 | LT14: 1422 | LU14: 1156 | LV14: 2309 | LW14: 1946 | LX14: 2240 | LY14: 2080 | LZ14: 1147 | MA14: 1552 | MB14: 2102 | MC14: 2080 | MD14: 2173 | ME14: 2499 | MF14: 1929 | MG14: 1385 | MH14: 2318 | MI14: 2416 | MJ14: 2580 | MK14: 2625 | ML14: 1832 | MM14: 2002 | MN14: 3023 | MO14: 2778 | MP14: 3811 | MQ14: 4104 | MR14: 2067 | MS14: 1719 | MT14: 2848 | MU14: 2749 | MV14: 3906 | MW14: 3452
A15: 4 | B15: 440 | C15: 283 | D15: 473 | E15: 465 | F15: 591 | G15: 534 | H15: 1006 | I15: 973 | J15: 1067 | K15: 800 | L15: 1429 | M15: 900 | N15: 553 | O15: 487 | P15: 1042 | Q15: 1014 | R15: 1040 | S15: 911 | T15: 820 | U15: 904 | V15: 1035 | W15: 1121 | X15: 1295 | Y15: 1003 | Z15: 1056 | AA15: 913 | AB15: 1180 | AC15: 1348 | AD15: 1839 | AE15: 1841 | AF15: 1080 | AG15: 1123 | AH15: 1849 | AI15: 1130 | AJ15: 2018 | AK15: 1310 | AL15: 741 | AM15: 665 | AN15: 1110 | AO15: 839 | AP15: 1374 | AQ15: 1288 | AR15: 2007 | AS15: 1538 | AT15: 2226 | AU15: 1704 | AV15: 2356 | AW15: 2211 | AX15: 1153 | AY15: 1470 | AZ15: 1745 | BA15: 1997 | BB15: 2710 | BC15: 2224 | BD15: 1743 | BE15: 1459 | BF15: 2516 | BG15: 2038 | BH15: 2583 | BI15: 2528 | BJ15: 1574 | BK15: 1989 | BL15: 2853 | BM15: 2285 | BN15: 3868 | BO15: 3471 | BP15: 2058 | BQ15: 1388 | BR15: 2719 | BS15: 2668 | BT15: 3431 | BU15: 3048 | BV15: 381 | BW15: 261 | BX15: 413 | BY15: 434 | BZ15: 597 | CA15: 573 | CB15: 553 | CC15: 682 | CD15: 1122 | CE15: 1098 | CF15: 915 | CG15: 1027 | CH15: 656 | CI15: 576 | CJ15: 1137 | CK15: 971 | CL15: 1120 | CM15: 900 | CN15: 750 | CO15: 785 | CP15: 1108 | CQ15: 1098 | CR15: 1426 | CS15: 1136 | CT15: 1032 | CU15: 838 | CV15: 1262 | CW15: 1125 | CX15: 1323 | CY15: 1511 | CZ15: 1175 | DA15: 865 | DB15: 1642 | DC15: 1322 | DD15: 1755 | DE15: 1427 | DF15: 700 | DG15: 646 | DH15: 1000 | DI15: 1095 | DJ15: 1277 | DK15: 1286 | DL15: 2037 | DM15: 1480 | DN15: 1939 | DO15: 1766 | DP15: 2670 | DQ15: 2006 | DR15: 1214 | DS15: 1150 | DT15: 1831 | DU15: 2055 | DV15: 2250 | DW15: 2458 | DX15: 1797 | DY15: 1635 | DZ15: 2279 | EA15: 1831 | EB15: 2812 | EC15: 2479 | ED15: 1486 | EE15: 1625 | EF15: 3004 | EG15: 2767 | EH15: 3848 | EI15: 3747 | EJ15: 2226 | EK15: 1540 | EL15: 3389 | EM15: 2605 | EN15: 3846 | EO15: 3296 | EP15: 441 | EQ15: 304 | ER15: 585 | ES15: 471 | ET15: 640 | EU15: 700 | EV15: 784 | EW15: 952 | EX15: 1171 | EY15: 826 | EZ15: 1061 | FA15: 1256 | FB15: 373 | FC15: 470 | FD15: 772 | FE15: 1101 | FF15: 1180 | FG15: 1098 | FH15: 614 | FI15: 648 | FJ15: 1084 | FK15: 921 | FL15: 1219 | FM15: 1256 | FN15: 832 | FO15: 563 | FP15: 1522 | FQ15: 1332 | FR15: 1808 | FS15: 1559 | FT15: 1009 | FU15: 805 | FV15: 1333 | FW15: 1270 | FX15: 1619 | FY15: 1567 | FZ15: 561 | GA15: 679 | GB15: 1158 | GC15: 874 | GD15: 1342 | GE15: 1316 | GF15: 1587 | GG15: 1278 | GH15: 2105 | GI15: 1832 | GJ15: 2551 | GK15: 2178 | GL15: 1198 | GM15: 1274 | GN15: 2095 | GO15: 1982 | GP15: 2662 | GQ15: 2551 | GR15: 1961 | GS15: 1570 | GT15: 2262 | GU15: 2013 | GV15: 2901 | GW15: 2280 | GX15: 1755 | GY15: 1741 | GZ15: 3097 | HA15: 2907 | HB15: 3546 | HC15: 3864 | HD15: 2021 | HE15: 1759 | HF15: 3146 | HG15: 2862 | HH15: 3987 | HI15: 3429 | HJ15: 218 | HK15: 341 | HL15: 464 | HM15: 550 | HN15: 671 | HO15: 607 | HP15: 664 | HQ15: 740 | HR15: 1154 | HS15: 1027 | HT15: 1242 | HU15: 927 | HV15: 726 | HW15: 663 | HX15: 999 | HY15: 853 | HZ15: 693 | IA15: 1445 | IB15: 1183 | IC15: 948 | ID15: 1276 | IE15: 847 | IF15: 1401 | IG15: 1118 | IH15: 945 | II15: 888 | IJ15: 1274 | IK15: 1435 | IL15: 1787 | IM15: 1920 | IN15: 1159 | IO15: 932 | IP15: 1734 | IQ15: 1223 | IR15: 1741 | IS15: 1679 | IT15: 719 | IU15: 571 | IV15: 895 | IW15: 860 | IX15: 1257 | IY15: 1399 | IZ15: 1969 | JA15: 1200 | JB15: 1995 | JC15: 1756 | JD15: 2020 | JE15: 2029 | JF15: 1164 | JG15: 1181 | JH15: 2235 | JI15: 1875 | JJ15: 2630 | JK15: 2293 | JL15: 1849 | JM15: 1553 | JN15: 2520 | JO15: 2004 | JP15: 2762 | JQ15: 2355 | JR15: 1560 | JS15: 1598 | JT15: 2954 | JU15: 3157 | JV15: 3938 | JW15: 3420 | JX15: 1768 | JY15: 1555 | JZ15: 3039 | KA15: 2806 | KB15: 3707 | KC15: 3292 | KD15: 289 | KE15: 368 | KF15: 485 | KG15: 457 | KH15: 677 | KI15: 627 | KJ15: 810 | KK15: 862 | KL15: 1211 | KM15: 1021 | KN15: 1112 | KO15: 1291 | KP15: 440 | KQ15: 522 | KR15: 786 | KS15: 908 | KT15: 1192 | KU15: 1225 | KV15: 1011 | KW15: 998 | KX15: 1253 | KY15: 1049 | KZ15: 1396 | LA15: 1008 | LB15: 850 | LC15: 967 | LD15: 1535 | LE15: 1199 | LF15: 1617 | LG15: 1499 | LH15: 1074 | LI15: 848 | LJ15: 1344 | LK15: 1296 | LL15: 1773 | LM15: 1776 | LN15: 579 | LO15: 711 | LP15: 1001 | LQ15: 977 | LR15: 1200 | LS15: 1123 | LT15: 1422 | LU15: 1156 | LV15: 2309 | LW15: 1946 | LX15: 2240 | LY15: 2080 | LZ15: 1147 | MA15: 1552 | MB15: 2099 | MC15: 2080 | MD15: 2171 | ME15: 2499 | MF15: 1929 | MG15: 1385 | MH15: 2321 | MI15: 2416 | MJ15: 2580 | MK15: 2638 | ML15: 1836 | MM15: 2002 | MN15: 3022 | MO15: 2756 | MP15: 3811 | MQ15: 4104 | MR15: 2068 | MS15: 1719 | MT15: 2851 | MU15: 2728 | MV15: 3900 | MW15: 3456
A16: 5 | B16: 440 | C16: 283 | D16: 473 | E16: 469 | F16: 591 | G16: 534 | H16: 1006 | I16: 973 | J16: 1067 | K16: 800 | L16: 1429 | M16: 900 | N16: 553 | O16: 487 | P16: 1040 | Q16: 1014 | R16: 1041 | S16: 907 | T16: 820 | U16: 904 | V16: 1035 | W16: 1121 | X16: 1294 | Y16: 999 | Z16: 1056 | AA16: 913 | AB16: 1179 | AC16: 1348 | AD16: 1842 | AE16: 1841 | AF16: 1080 | AG16: 1123 | AH16: 1853 | AI16: 1130 | AJ16: 2020 | AK16: 1313 | AL16: 741 | AM16: 665 | AN16: 1112 | AO16: 839 | AP16: 1373 | AQ16: 1288 | AR16: 2007 | AS16: 1538 | AT16: 2226 | AU16: 1704 | AV16: 2356 | AW16: 2211 | AX16: 1153 | AY16: 1462 | AZ16: 1750 | BA16: 1997 | BB16: 2704 | BC16: 2217 | BD16: 1743 | BE16: 1459 | BF16: 2516 | BG16: 2038 | BH16: 2580 | BI16: 2545 | BJ16: 1574 | BK16: 1970 | BL16: 2853 | BM16: 2293 | BN16: 3868 | BO16: 3467 | BP16: 2058 | BQ16: 1388 | BR16: 2717 | BS16: 2685 | BT16: 3432 | BU16: 3053 | BV16: 381 | BW16: 261 | BX16: 413 | BY16: 434 | BZ16: 597 | CA16: 573 | CB16: 553 | CC16: 682 | CD16: 1122 | CE16: 1098 | CF16: 915 | CG16: 1027 | CH16: 656 | CI16: 576 | CJ16: 1137 | CK16: 979 | CL16: 1120 | CM16: 900 | CN16: 750 | CO16: 785 | CP16: 1107 | CQ16: 1098 | CR16: 1425 | CS16: 1147 | CT16: 1032 | CU16: 838 | CV16: 1262 | CW16: 1125 | CX16: 1323 | CY16: 1511 | CZ16: 1175 | DA16: 865 | DB16: 1640 | DC16: 1321 | DD16: 1756 | DE16: 1425 | DF16: 700 | DG16: 643 | DH16: 1000 | DI16: 1095 | DJ16: 1277 | DK16: 1297 | DL16: 2037 | DM16: 1480 | DN16: 1939 | DO16: 1766 | DP16: 2670 | DQ16: 2006 | DR16: 1214 | DS16: 1150 | DT16: 1833 | DU16: 2074 | DV16: 2250 | DW16: 2458 | DX16: 1797 | DY16: 1635 | DZ16: 2282 | EA16: 1862 | EB16: 2788 | EC16: 2467 | ED16: 1487 | EE16: 1625 | EF16: 3001 | EG16: 2775 | EH16: 3854 | EI16: 3743 | EJ16: 2225 | EK16: 1525 | EL16: 3387 | EM16: 2621 | EN16: 3834 | EO16: 3292 | EP16: 441 | EQ16: 304 | ER16: 585 | ES16: 471 | ET16: 640 | EU16: 694 | EV16: 784 | EW16: 952 | EX16: 1171 | EY16: 826 | EZ16: 1061 | FA16: 1256 | FB16: 373 | FC16: 470 | FD16: 772 | FE16: 1101 | FF16: 1179 | FG16: 1100 | FH16: 614 | FI16: 648 | FJ16: 1084 | FK16: 921 | FL16: 1221 | FM16: 1244 | FN16: 832 | FO16: 563 | FP16: 1522 | FQ16: 1334 | FR16: 1813 | FS16: 1559 | FT16: 1013 | FU16: 805 | FV16: 1329 | FW16: 1271 | FX16: 1621 | FY16: 1570 | FZ16: 561 | GA16: 679 | GB16: 1160 | GC16: 870 | GD16: 1342 | GE16: 1316 | GF16: 1587 | GG16: 1278 | GH16: 2105 | GI16: 1832 | GJ16: 2551 | GK16: 2178 | GL16: 1199 | GM16: 1275 | GN16: 2094 | GO16: 1978 | GP16: 2662 | GQ16: 2551 | GR16: 1961 | GS16: 1570 | GT16: 2252 | GU16: 2013 | GV16: 2894 | GW16: 2269 | GX16: 1754 | GY16: 1741 | GZ16: 3097 | HA16: 2884 | HB16: 3546 | HC16: 3864 | HD16: 2020 | HE16: 1737 | HF16: 3152 | HG16: 2841 | HH16: 3979 | HI16: 3423 | HJ16: 218 | HK16: 341 | HL16: 464 | HM16: 548 | HN16: 671 | HO16: 607 | HP16: 664 | HQ16: 740 | HR16: 1154 | HS16: 1027 | HT16: 1242 | HU16: 927 | HV16: 726 | HW16: 663 | HX16: 999 | HY16: 853 | HZ16: 694 | IA16: 1445 | IB16: 1183 | IC16: 948 | ID16: 1276 | IE16: 841 | IF16: 1397 | IG16: 1131 | IH16: 945 | II16: 888 | IJ16: 1279 | IK16: 1443 | IL16: 1787 | IM16: 1920 | IN16: 1159 | IO16: 932 | IP16: 1727 | IQ16: 1231 | IR16: 1742 | IS16: 1670 | IT16: 719 | IU16: 571 | IV16: 893 | IW16: 860 | IX16: 1256 | IY16: 1399 | IZ16: 1969 | JA16: 1200 | JB16: 1995 | JC16: 1756 | JD16: 2020 | JE16: 2029 | JF16: 1166 | JG16: 1181 | JH16: 2235 | JI16: 1875 | JJ16: 2630 | JK16: 2311 | JL16: 1849 | JM16: 1553 | JN16: 2519 | JO16: 1992 | JP16: 2751 | JQ16: 2362 | JR16: 1560 | JS16: 1583 | JT16: 2951 | JU16: 3157 | JV16: 3947 | JW16: 3421 | JX16: 1772 | JY16: 1542 | JZ16: 3040 | KA16: 2773 | KB16: 3700 | KC16: 3279 | KD16: 289 | KE16: 368 | KF16: 485 | KG16: 455 | KH16: 677 | KI16: 617 | KJ16: 810 | KK16: 862 | KL16: 1211 | KM16: 1021 | KN16: 1112 | KO16: 1291 | KP16: 440 | KQ16: 522 | KR16: 786 | KS16: 908 | KT16: 1192 | KU16: 1225 | KV16: 1011 | KW16: 998 | KX16: 1253 | KY16: 1049 | KZ16: 1398 | LA16: 1005 | LB16: 850 | LC16: 967 | LD16: 1537 | LE16: 1198 | LF16: 1617 | LG16: 1499 | LH16: 1074 | LI16: 848 | LJ16: 1345 | LK16: 1281 | LL16: 1772 | LM16: 1769 | LN16: 579 | LO16: 711 | LP16: 1001 | LQ16: 981 | LR16: 1201 | LS16: 1102 | LT16: 1422 | LU16: 1156 | LV16: 2309 | LW16: 1946 | LX16: 2240 | LY16: 2080 | LZ16: 1146 | MA16: 1552 | MB16: 2100 | MC16: 2080 | MD16: 2172 | ME16: 2499 | MF16: 1929 | MG16: 1385 | MH16: 2316 | MI16: 2416 | MJ16: 2567 | MK16: 2644 | ML16: 1828 | MM16: 2002 | MN16: 3023 | MO16: 2777 | MP16: 3811 | MQ16: 4104 | MR16: 2069 | MS16: 1719 | MT16: 2848 | MU16: 2752 | MV16: 3908 | MW16: 3434
A17: 6 | B17: 440 | C17: 283 | D17: 473 | E17: 464 | F17: 591 | G17: 534 | H17: 1006 | I17: 973 | J17: 1067 | K17: 800 | L17: 1429 | M17: 900 | N17: 553 | O17: 487 | P17: 1042 | Q17: 1014 | R17: 1040 | S17: 897 | T17: 820 | U17: 904 | V17: 1035 | W17: 1110 | X17: 1295 | Y17: 1009 | Z17: 1056 | AA17: 913 | AB17: 1180 | AC17: 1348 | AD17: 1842 | AE17: 1841 | AF17: 1080 | AG17: 1123 | AH17: 1853 | AI17: 1139 | AJ17: 2015 | AK17: 1309 | AL17: 741 | AM17: 665 | AN17: 1113 | AO17: 839 | AP17: 1374 | AQ17: 1288 | AR17: 2007 | AS17: 1538 | AT17: 2226 | AU17: 1704 | AV17: 2356 | AW17: 2211 | AX17: 1153 | AY17: 1468 | AZ17: 1749 | BA17: 1997 | BB17: 2710 | BC17: 2233 | BD17: 1743 | BE17: 1459 | BF17: 2516 | BG17: 2038 | BH17: 2564 | BI17: 2468 | BJ17: 1571 | BK17: 1992 | BL17: 2853 | BM17: 2276 | BN17: 3863 | BO17: 3458 | BP17: 2048 | BQ17: 1388 | BR17: 2716 | BS17: 2667 | BT17: 3437 | BU17: 3050 | BV17: 381 | BW17: 261 | BX17: 413 | BY17: 434 | BZ17: 595 | CA17: 573 | CB17: 553 | CC17: 682 | CD17: 1122 | CE17: 1098 | CF17: 915 | CG17: 1027 | CH17: 657 | CI17: 576 | CJ17: 1137 | CK17: 971 | CL17: 1120 | CM17: 900 | CN17: 750 | CO17: 785 | CP17: 1107 | CQ17: 1098 | CR17: 1426 | CS17: 1128 | CT17: 1032 | CU17: 838 | CV17: 1262 | CW17: 1125 | CX17: 1323 | CY17: 1511 | CZ17: 1175 | DA17: 865 | DB17: 1641 | DC17: 1328 | DD17: 1751 | DE17: 1434 | DF17: 700 | DG17: 644 | DH17: 1000 | DI17: 1095 | DJ17: 1277 | DK17: 1296 | DL17: 2037 | DM17: 1480 | DN17: 1939 | DO17: 1766 | DP17: 2670 | DQ17: 2006 | DR17: 1214 | DS17: 1150 | DT17: 1831 | DU17: 2071 | DV17: 2250 | DW17: 2458 | DX17: 1797 | DY17: 1635 | DZ17: 2281 | EA17: 1859 | EB17: 2780 | EC17: 2468 | ED17: 1482 | EE17: 1625 | EF17: 3009 | EG17: 2772 | EH17: 3851 | EI17: 3730 | EJ17: 2228 | EK17: 1531 | EL17: 3396 | EM17: 2606 | EN17: 3843 | EO17: 3276 | EP17: 441 | EQ17: 304 | ER17: 585 | ES17: 471 | ET17: 640 | EU17: 694 | EV17: 784 | EW17: 952 | EX17: 1171 | EY17: 826 | EZ17: 1061 | FA17: 1256 | FB17: 373 | FC17: 470 | FD17: 772 | FE17: 1101 | FF17: 1179 | FG17: 1094 | FH17: 614 | FI17: 648 | FJ17: 1084 | FK17: 921 | FL17: 1221 | FM17: 1243 | FN17: 832 | FO17: 563 | FP17: 1522 | FQ17: 1332 | FR17: 1811 | FS17: 1559 | FT17: 1009 | FU17: 805 | FV17: 1334 | FW17: 1263 | FX17: 1621 | FY17: 1576 | FZ17: 561 | GA17: 679 | GB17: 1162 | GC17: 876 | GD17: 1342 | GE17: 1316 | GF17: 1587 | GG17: 1278 | GH17: 2105 | GI17: 1832 | GJ17: 2551 | GK17: 2178 | GL17: 1201 | GM17: 1267 | GN17: 2095 | GO17: 1968 | GP17: 2662 | GQ17: 2551 | GR17: 1961 | GS17: 1570 | GT17: 2260 | GU17: 2013 | GV17: 2911 | GW17: 2260 | GX17: 1755 | GY17: 1741 | GZ17: 3097 | HA17: 2885 | HB17: 3546 | HC17: 3864 | HD17: 2026 | HE17: 1762 | HF17: 3150 | HG17: 2844 | HH17: 3973 | HI17: 3416 | HJ17: 218 | HK17: 341 | HL17: 464 | HM17: 543 | HN17: 671 | HO17: 607 | HP17: 664 | HQ17: 740 | HR17: 1154 | HS17: 1027 | HT17: 1242 | HU17: 927 | HV17: 726 | HW17: 663 | HX17: 999 | HY17: 853 | HZ17: 693 | IA17: 1445 | IB17: 1183 | IC17: 948 | ID17: 1276 | IE17: 846 | IF17: 1390 | IG17: 1122 | IH17: 945 | II17: 886 | IJ17: 1277 | IK17: 1446 | IL17: 1787 | IM17: 1920 | IN17: 1159 | IO17: 932 | IP17: 1734 | IQ17: 1236 | IR17: 1742 | IS17: 1686 | IT17: 719 | IU17: 571 | IV17: 893 | IW17: 860 | IX17: 1255 | IY17: 1399 | IZ17: 1969 | JA17: 1200 | JB17: 1995 | JC17: 1756 | JD17: 2019 | JE17: 2029 | JF17: 1164 | JG17: 1181 | JH17: 2235 | JI17: 1875 | JJ17: 2630 | JK17: 2298 | JL17: 1849 | JM17: 1553 | JN17: 2520 | JO17: 2001 | JP17: 2760 | JQ17: 2350 | JR17: 1560 | JS17: 1594 | JT17: 2948 | JU17: 3157 | JV17: 3940 | JW17: 3420 | JX17: 1765 | JY17: 1571 | JZ17: 3038 | KA17: 2802 | KB17: 3701 | KC17: 3257 | KD17: 289 | KE17: 368 | KF17: 485 | KG17: 461 | KH17: 677 | KI17: 609 | KJ17: 810 | KK17: 862 | KL17: 1211 | KM17: 1021 | KN17: 1112 | KO17: 1291 | KP17: 440 | KQ17: 522 | KR17: 786 | KS17: 908 | KT17: 1192 | KU17: 1225 | KV17: 1011 | KW17: 998 | KX17: 1253 | KY17: 1049 | KZ17: 1396 | LA17: 1007 | LB17: 850 | LC17: 967 | LD17: 1533 | LE17: 1199 | LF17: 1617 | LG17: 1499 | LH17: 1074 | LI17: 848 | LJ17: 1337 | LK17: 1291 | LL17: 1776 | LM17: 1758 | LN17: 579 | LO17: 711 | LP17: 999 | LQ17: 977 | LR17: 1200 | LS17: 1111 | LT17: 1422 | LU17: 1156 | LV17: 2309 | LW17: 1946 | LX17: 2240 | LY17: 2080 | LZ17: 1146 | MA17: 1552 | MB17: 2097 | MC17: 2080 | MD17: 2172 | ME17: 2499 | MF17: 1929 | MG17: 1385 | MH17: 2316 | MI17: 2416 | MJ17: 2581 | MK17: 2643 | ML17: 1831 | MM17: 2002 | MN17: 3025 | MO17: 2768 | MP17: 3811 | MQ17: 4104 | MR17: 2069 | MS17: 1719 | MT17: 2849 | MU17: 2762 | MV17: 3901 | MW17: 3455
